Workbook
Name s: [30]梁!$X1*1.2
Name \q: #REF!
Name _001年.xls: #REF!
Name __________TP5125: [1]材料!$F$7
Name _: #REF!
Name page1: #N/A
Name lap: [2]General!$B$2:$G$9
Name A_1: "$"
Name A_1___1: "$"
Name CGFS000001: [3]下拉!$H$3:$H$159
Name GLLB_A: [3]下拉!$D$3:$D$8
Name A_1___2: "$"
Name A_1___4: "$"
Name A_2: "$"
Name A_1___0: "$"
Name A_2___0: "$"
Name ___xlfn_FINV: #N/A
Name __xlfn_FINV: #N/A
Name _4_4.2_0.1_3.8_4__0.6_0.14: [4]土方!#REF!
Name _ae1: '[5]21'!$B$1:$B$802
Name _W200: '[7]21'!$B$1:$B$802
Name _xlfn_FINV: #N/A
Name a: NA()
Name A_2___1: "$"
Name A_2___2: "$"
Name A_2___4: "$"
Name A_5: "$"
Name A_6: "$"
Name aaaa: EVALUATE([8]工程量A6!XFD1)
Name AccountBase: [9]貨品科目!$B$5:$E$857
Name ad: '[10]21'!$A$1:$A$802
Name ae: '[10]21'!$B$1:$B$802
Name B_1: "$"
Name B_1___0: "$"
Name B_1___1: "$"
Name B_1___2: "$"
Name B_1___4: "$"
Name B_2: "$"
Name B_2___0: "$"
Name B_2___1: "$"
Name B_2___2: "$"
Name B_2___4: "$"
Name B01_: "$"
Name B01____0: "$"
Name B01____1: "$"
Name B01____2: "$"
Name B01____4: "$"
Name B02_: "$"
Name B02____0: "$"
Name B02____1: "$"
Name B02____2: "$"
Name B02____4: "$"
Name B03_: "$"
Name B03____0: "$"
Name B03____1: "$"
Name B03____2: "$"
Name B03____4: "$"
Name B04_: "$"
Name B04____0: "$"
Name B04____1: "$"

Sheet 汇总表
A1: 成华区迎晖路194号住宅、商业及配套设施项目幕墙工程成本汇总表
A2: 序号 | B2: 项目名称 | C2: 暂估幕墙面积 （㎡） | D2: 含税总价 （元） | E2: 含税单方造价 （元/㎡） | F2: 备注 | J2: 人数 | K2: 工资 | L2: 工期 | M2: 小计
A3: 1 | B3: 排屋幕墙 | C3: =排屋工程量清单!D118*11 -> 40189.114 | D3: =排屋工程量清单!G118*11 -> 37681753 | E3: =D3/C3 -> 937.61092 | F3: 图纸不齐，工程量暂定 | I3: 项目经理 | J3: 1 | K3: 16000 | L3: 24 | M3: =L3*K3*J3 -> 384000
A4: 2 | B4: 1#2#商业幕墙 | C4: ='商业工程量清单 '!D104 -> 8319.4105 | D4: ='商业工程量清单 '!G104 -> 7934002.9 | E4: =D4/C4 -> 953.67369 | I4: 技术负责人 | J4: 1 | K4: 13000 | L4: 16 | M4: =L4*K4*J4 -> 208000
A5: 3 | B5: 1#2#塔楼 | C5: 30816.26 | D5: =[117]塔楼报价汇总!$G$30 -> 37494777 | E5: =D5/C5 -> 1216.7206 | F5: 图纸不齐，工程量暂定 | I5: 幕墙设计 | J5: 2 | K5: 13000 | L5: 16 | M5: =L5*K5*J5 -> 416000
A6: 4 | B6: 暂定管理人员工资 | D6: =M14 -> 2165000 | F6: 最终据实统计 | G6: =D6/D13 -> 0.025137725 | I6: 施工员 | J6: 1 | K6: 9000 | L6: 16 | M6: =L6*K6*J6 -> 144000
A7: 5 | B7: 暂定差旅费 | D7: 150000 | F7: 最终据实统计 | G7: =D7/D13 -> 0.0017416438 | I7: 安全员 | J7: 1 | K7: 9000 | L7: 16 | M7: =L7*K7*J7 -> 144000
A8: 6 | B8: 暂定办公费用 | D8: 50000 | F8: 最终据实统计 | G8: =D8/D13 -> 0.00058054793 | I8: 材料员 | J8: 1 | K8: 8000 | L8: 8 | M8: =L8*K8*J8 -> 64000
A9: 7 | B9: 暂定房租 | D9: 80000 | F9: 最终据实统计 | G9: =D9/D13 -> 0.00092887669 | I9: 库管 | J9: 1 | K9: 5000 | L9: 16 | M9: =L9*K9*J9 -> 80000
A10: 8 | B10: 暂定检测费 | D10: 450000 | F10: 最终据实统计 | G10: =D10/D13 -> 0.0052249314 | I10: 劳务资料员 | J10: 1 | K10: 8000 | L10: 16 | M10: =L10*K10*J10 -> 128000
A11: 9 | B11: 过节招待费 | D11: 120000 | F11: 最终据实统计 | G11: =D11/D13 -> 0.001393315 | I11: 质量员 | J11: 1 | K11: 12000 | L11: 16 | M11: =L11*K11*J11 -> 192000
I12: 商务 | J12: 1 | K12: 15000 | L12: 24 | M12: =L12*K12*J12 -> 360000
B13: 合计 | C13: =SUM(C3:C5) -> 79324.785 | D13: =SUM(D3:D12) -> 86125533 | G13: =D13/C13 -> 1085.733 | I13: 监理 | J13: 1 | K13: 2500 | L13: 18 | M13: =L13*K13*J13 -> 45000
I14: 合计 | J14: =SUM(J3:J13) -> 12 | M14: =SUM(M3:M13) -> 2165000

Sheet 排屋工程量清单
A1: 成都塔子山11#楼工程量清单（成本）
A2: 序号 | B2: 项目名称 | C2: 部位 | D2: 工程量 | E2: 单位 | F2: 含税单价（元） | G2: 含税合价（元） | H2: 备注
A3: 一 | B3: 80系列断桥隔热铝合金窗 | D3: =SUM(D4:D21) -> 115.204 | G3: =SUM(G4:G21) -> 86828.226
A4: 1 | B4: LMC6117G | D4: =4.05*1.75*2 -> 14.175 | E4: m2 | F4: =VLOOKUP(B4,'综合单价分析表 (11#楼)'!A:I,9,) -> 808.61369 | G4: =+F4*D4 -> 11462.099
A5: =MAX($A$3:$A4)+1 -> 2 | B5: LC1227 | D5: =1.1*1.75*2 -> 3.85 | E5: m2 | F5: =F4 -> 808.61369 | G5: =+F5*D5 -> 3113.1627
A6: =MAX($A$3:$A5)+1 -> 3 | B6: LMC4517G | D6: =2.55*1.75 -> 4.4625 | E6: m2 | F6: =F4 -> 808.61369 | G6: =+F6*D6 -> 3608.4386
A7: =MAX($A$3:$A6)+1 -> 4 | B7: LC4107C | D7: =4.05*0.75 -> 3.0375 | E7: m2 | F7: =F4 -> 808.61369 | G7: =+F7*D7 -> 2456.1641
A8: =MAX($A$3:$A7)+1 -> 5 | B8: LC6321/LC631反 | D8: =6.2*2*2 -> 24.8 | E8: m2 | F8: =F4 -> 808.61369 | G8: =+F8*D8 -> 20053.619
A9: =MAX($A$3:$A8)+1 -> 6 | B9: LC0717C | D9: =0.75*1.75*3 -> 3.9375 | E9: m2 | F9: =F4 -> 808.61369 | G9: =+F9*D9 -> 3183.9164
B10: LC0617B | D10: =0.75*1.75*3 -> 3.9375 | E10: m2 | F10: =F4 -> 808.61369 | G10: =+F10*D10 -> 3183.9164
A11: =MAX($A$3:$A9)+1 -> 7 | B11: LC5121(平开窗) | C11: 5+12A+5㎜钢化中空玻璃 | D11: =5*2 -> 10 | E11: m2 | F11: =F4 -> 808.61369 | G11: =+F11*D11 -> 8086.1369 | H11: 地下室夹层
A12: =MAX($A$3:$A11)+1 -> 8 | B12: LC1015B(平开窗) | C12: 5+12A+5㎜钢化中空玻璃 | D12: =1*1.55*2 -> 3.1 | E12: m2 | F12: =F11 -> 808.61369 | G12: =+F12*D12 -> 2506.7024 | H12: 地下室夹层
A13: =MAX($A$3:$A12)+1 -> 9 | B13: LC1015C(平开窗) | C13: 5+12A+5㎜钢化中空玻璃 | D13: =1.05*1.5 -> 1.575 | E13: m2 | F13: =F11 -> 808.61369 | G13: =+F13*D13 -> 1273.5666 | H13: 地下室夹层
A14: =MAX($A$3:$A13)+1 -> 10 | B14: LC3023(固定窗) | C14: 12+12A+12㎜钢化中空玻璃 | D14: =3*2.3 -> 6.9 | E14: m2 | F14: 600 | G14: =+F14*D14 -> 4140 | H14: 地下室夹层
A15: =MAX($A$3:$A14)+1 -> 11 | B15: LC1215C(平开窗) | C15: 5+12A+5㎜钢化中空玻璃 | D15: =1.25*1.55 -> 1.9375 | E15: m2 | F15: =F11 -> 808.61369 | G15: =+F15*D15 -> 1566.689 | H15: 地下室夹层
A16: =MAX($A$3:$A15)+1 -> 12 | B16: TLM3123(推拉门) | C16: 6+12A+6㎜钢化中空玻璃 | D16: =3.1*2.3 -> 7.13 | E16: m2 | F16: =F4 -> 808.61369 | G16: =+F16*D16 -> 5765.4156 | H16: 地下室夹层
A17: =MAX($A$3:$A16)+1 -> 13 | B17: LC0823A(固定窗) | C17: 5+12A+5㎜钢化中空玻璃 | D17: =0.85*2.3 -> 1.955 | E17: m2 | F17: =F14 -> 600 | G17: =+F17*D17 -> 1173 | H17: 地下室夹层
A18: =MAX($A$3:$A17)+1 -> 14 | B18: LC2421A(固定窗) | C18: 12+12A+12㎜钢化中空玻璃 | D18: =2.55*2.15 -> 5.4825 | E18: m2 | F18: =F14 -> 600 | G18: =+F18*D18 -> 3289.5 | H18: 地下室一层
A19: =MAX($A$3:$A18)+1 -> 15 | B19: LC0913X(固定窗) | C19: 5+12A+5㎜钢化中空玻璃 | D19: =0.95*1.345 -> 1.27775 | E19: m2 | F19: =F14 -> 600 | G19: =+F19*D19 -> 766.65 | H19: 地下室一层
A20: =MAX($A$3:$A19)+1 -> 16 | B20: LC2754B(固定窗) | C20: 15+12A+15㎜钢化中空玻璃 | D20: =2.7*5.45 -> 14.715 | E20: m2 | F20: =F14 -> 600 | G20: =+F20*D20 -> 8829 | H20: 地下室一层
A21: =MAX($A$3:$A20)+1 -> 17 | B21: TLM1223X(平开门) | C21: 5+12A+5㎜钢化中空玻璃 | D21: =1.25*2.345 -> 2.93125 | E21: m2 | F21: =F4 -> 808.61369 | G21: =+F21*D21 -> 2370.2489 | H21: 地下室一层
A22: 二 | B22: 幕墙式铝合金窗 | D22: =SUM(D23:D47) -> 515.11425 | G22: =SUM(G23:G47) -> 648486.36
A23: =MAX($A$3:$A22)+1 -> 18 | B23: LMC10425C | D23: =10.3*2.59 -> 26.677 | E23: m2 | F23: =VLOOKUP(B23,'综合单价分析表 (11#楼)'!A:I,9,) -> 1258.9175 | G23: =D23*F23 -> 33584.143 | H23: 系统门
A24: =MAX($A$3:$A23)+1 -> 19 | B24: LC4124X | D24: =4.162*(2.47+0.7) -> 13.19354 | E24: m2 | F24: =F23 -> 1258.9175 | G24: =D24*F24 -> 16609.579 | H24: 系统窗
A25: =MAX($A$3:$A24)+1 -> 20 | B25: LMC7825F | D25: =7.65*2.59 -> 19.8135 | E25: m2 | F25: =F23 -> 1258.9175 | G25: =D25*F25 -> 24943.562 | H25: 系统门
A26: =MAX($A$3:$A25)+1 -> 21 | B26: LC3724X | D26: =3.762*(2.47+0.7) -> 11.92554 | E26: m2 | F26: =F23 -> 1258.9175 | G26: =D26*F26 -> 15013.271 | H26: 系统窗
A27: =MAX($A$3:$A26)+1 -> 22 | B27: LMC10425F | D27: =10.3*2.59 -> 26.677 | E27: m2 | F27: =F23 -> 1258.9175 | G27: =D27*F27 -> 33584.143 | H27: 系统门
A28: =MAX($A$3:$A27)+1 -> 23 | B28: LC4024X | D28: =4.062*(2.47+0.7) -> 12.87654 | E28: m2 | F28: =F23 -> 1258.9175 | G28: =D28*F28 -> 16210.502 | H28: 系统窗
A29: =MAX($A$3:$A28)+1 -> 24 | B29: LC2822A/LC2822A反 | D29: =2.86*2.22*2 -> 12.6984 | E29: m2 | F29: =F23 -> 1258.9175 | G29: =D29*F29 -> 15986.238 | H29: 系统窗
A30: =MAX($A$3:$A29)+1 -> 25 | B30: LMC13726X/LMC13726X反 | D30: =13.714*2.71*2 -> 74.32988 | E30: m2 | F30: =F23 -> 1258.9175 | G30: =D30*F30 -> 93575.188 | H30: 系统门、系统窗
A31: =MAX($A$3:$A30)+1 -> 26 | B31: LMC4326X/LMC4326X反 | D31: =7.212*2.71*2 -> 39.08904 | E31: m2 | F31: =F23 -> 1258.9175 | G31: =D31*F31 -> 49209.877 | H31: 系统门
A32: =MAX($A$3:$A31)+1 -> 27 | B32: LC7326X | D32: =4.502*2.73 -> 12.29046 | E32: m2 | F32: =F23 -> 1258.9175 | G32: =D32*F32 -> 15472.675 | H32: 系统窗
A33: =MAX($A$3:$A32)+1 -> 28 | B33: LC8226X | D33: =7.913*2.71 -> 21.44423 | E33: m2 | F33: =F23 -> 1258.9175 | G33: =D33*F33 -> 26996.517 | H33: 系统门、系统窗
A34: =MAX($A$3:$A33)+1 -> 29 | B34: LC3126X | D34: =5.512*2.71 -> 14.93752 | E34: m2 | F34: =F23 -> 1258.9175 | G34: =D34*F34 -> 18805.106 | H34: 系统门
A35: =MAX($A$3:$A34)+1 -> 30 | B35: LC6526X | D35: =4.102*2.71 -> 11.11642 | E35: m2 | F35: =F23 -> 1258.9175 | G35: =D35*F35 -> 13994.656 | H35: 系统窗
A36: =MAX($A$3:$A35)+1 -> 31 | B36: LC4426X | D36: =4.402*2.73 -> 12.01746 | E36: m2 | F36: =F23 -> 1258.9175 | G36: =D36*F36 -> 15128.991 | H36: 系统窗
A37: =MAX($A$3:$A36)+1 -> 32 | B37: LC9325X/LC9325X反 | D37: =9.352*2.63*2 -> 49.19152 | E37: m2 | F37: =F23 -> 1258.9175 | G37: =D37*F37 -> 61928.067 | H37: 系统窗
A38: =MAX($A$3:$A37)+1 -> 33 | B38: LC1624H | D38: =1.61*2.52*3 -> 12.1716 | E38: m2 | F38: =F24 -> 1258.9175 | G38: =D38*F38 -> 15323.041 | H38: 固定窗
A39: =MAX($A$3:$A38)+1 -> 34 | B39: LC5726X | D39: =5.69*2.64 -> 15.0216 | E39: m2 | F39: =F25 -> 1258.9175 | G39: =D39*F39 -> 18910.955 | H39: 系统门
A40: =MAX($A$3:$A39)+1 -> 35 | B40: LC4425C | D40: =3.96*2.63 -> 10.4148 | E40: m2 | F40: =F23 -> 1258.9175 | G40: =D40*F40 -> 13111.374 | H40: 系统窗
...

Sheet 商业工程量清单 
A1: 成都塔子山1#2#商业工程量清单（成本）
A2: 序号 | B2: 项目名称 | C2: 部位 | D2: 工程量 | E2: 单位 | F2: 含税单价（元） | G2: 含税合价（元） | H2: 备注
A3: 一 | B3: 玻璃幕墙 | D3: =SUM(D4:D43) -> 1528.5488 | G3: =SUM(G4:G43) -> 1931614 | J3: ='工程量计算式（商业）'!E2 -> 1528.5488 | K3: =D3-J3 -> 0
A4: 1 | B4: 首层座槽式玻璃幕墙（15+2.25SGP+15㎜全超白钢化夹层玻璃）（超宽） | C4: 1#楼南立面2/01~1/01轴 | D4: =SUMIF('工程量计算式（商业）'!A:A,B4,'工程量计算式（商业）'!E:E) -> 25.92 | E4: m2 | F4: =VLOOKUP(B4,'综合单价分析表（商业）'!A:I,9,) -> 1800.8283 | G4: =+F4*D4 -> 46677.469
A5: =MAX($A$3:$A4)+1 -> 2 | B5: 首层座槽式玻璃幕墙（12Low-E(双银)+12A+12全超白钢化中空玻璃） | C5: 1#楼南立面1~2轴 | D5: =SUMIF('工程量计算式（商业）'!A:A,B5,'工程量计算式（商业）'!E:E) -> 10.98 | E5: m2 | F5: =VLOOKUP(B5,'综合单价分析表（商业）'!A:I,9,) -> 617.41484 | G5: =+F5*D5 -> 6779.215
A6: =MAX($A$3:$A5)+1 -> 3 | B6: 首层座槽式玻璃幕墙（12Low-E(双银)+12A+12全超白钢化中空玻璃）（直+弯弧）（直段宽度300㎜+弧长942㎜，圆弧半径600㎜，高3600㎜） | C6: 1#楼南立面2/01~1/01轴 | D6: =SUMIF('工程量计算式（商业）'!A:A,B6,'工程量计算式（商业）'!E:E) -> 8.9424 | E6: m2 | F6: =VLOOKUP(B6,'综合单价分析表（商业）'!A:I,9,) -> 1662.2142 | G6: =+F6*D6 -> 14864.184
A7: =MAX($A$3:$A6)+1 -> 4 | B7: 首层座槽式玻璃幕墙（12+1.9SGP+12㎜全超白钢化夹层玻璃） | C7: 1#楼南立面2~22轴 | D7: =SUMIF('工程量计算式（商业）'!A:A,B7,'工程量计算式（商业）'!E:E) -> 258.624 | E7: m2 | F7: =VLOOKUP(B7,'综合单价分析表（商业）'!A:I,9,) -> 887.51902 | G7: =+F7*D7 -> 229533.72
A8: =MAX($A$3:$A7)+1 -> 5 | B8: 首层座槽式玻璃幕墙（12+1.9SGP+12㎜全超白钢化夹层玻璃）（弯弧）（弧长1414㎜，圆弧半径900㎜，高3600㎜） | C8: 1#楼南立面2~22轴 | D8: =SUMIF('工程量计算式（商业）'!A:A,B8,'工程量计算式（商业）'!E:E) -> 20.3616 | E8: m2 | F8: =VLOOKUP(B8,'综合单价分析表（商业）'!A:I,9,) -> 1344.225 | G8: =+F8*D8 -> 27370.571
A9: =MAX($A$3:$A8)+1 -> 6 | B9: 首层座槽式玻璃幕墙（10+1.9SGP+10Low-E(双银)+12A+12㎜全超白钢化夹层中空玻璃） | C9: 2#楼南立面5/01~4/01轴,12剖 | D9: =SUMIF('工程量计算式（商业）'!A:A,B9,'工程量计算式（商业）'!E:E) -> 63.36 | E9: m2 | F9: =VLOOKUP(B9,'综合单价分析表（商业）'!A:I,9,) -> 1138.0172 | G9: =+F9*D9 -> 72104.767
A10: =MAX($A$3:$A9)+1 -> 7 | B10: 首层座槽式玻璃幕墙（10+1.9SGP+10Low-E(双银)+12A+12㎜全超白钢化夹层中空玻璃）（弯弧）（弧长1414㎜，圆弧半径900㎜，高3600㎜） | C10: 2#楼南立面5/01~4/01轴,12剖 | D10: =SUMIF('工程量计算式（商业）'!A:A,B10,'工程量计算式（商业）'!E:E) -> 10.1808 | E10: m2 | F10: =VLOOKUP(B10,'综合单价分析表（商业）'!A:I,9,) -> 1879.7105 | G10: =+F10*D10 -> 19136.957
A11: =MAX($A$3:$A10)+1 -> 8 | B11: 首层座槽式玻璃幕墙（12+1.9SGP+12㎜全超白钢化夹层玻璃）（弯弧）（弧长1498㎜，圆弧半径900㎜，高3600㎜） | C11: 2#楼南立面2~18轴，10剖 | D11: =SUMIF('工程量计算式（商业）'!A:A,B11,'工程量计算式（商业）'!E:E) -> 9.4788 | E11: m2 | F11: =VLOOKUP(B11,'综合单价分析表（商业）'!A:I,9,) -> 1337.856 | G11: =+F11*D11 -> 12681.269
A12: =MAX($A$3:$A11)+1 -> 9 | B12: 首层座槽式玻璃幕墙（12+1.9SGP+12㎜全超白钢化夹层玻璃）（直+弯弧）（直段宽度840㎜+弧长1135㎜，圆弧半径900㎜，高3600㎜） | C12: 2#楼南立面2~18轴，10剖 | D12: =SUMIF('工程量计算式（商业）'!A:A,B12,'工程量计算式（商业）'!E:E) -> 7.11 | E12: m2 | F12: =VLOOKUP(B12,'综合单价分析表（商业）'!A:I,9,) -> 1573.6342 | G12: =+F12*D12 -> 11188.539
A13: =MAX($A$3:$A12)+1 -> 10 | B13: 首层座槽式玻璃幕墙（12+1.9SGP+12㎜全超白钢化夹层玻璃）（直+弯弧+直）（直段宽度840㎜+弧长1498㎜+直段宽度450㎜，圆弧半径900㎜，高3600㎜） | C13: 2#楼南立面2~18轴，10剖 | D13: =SUMIF('工程量计算式（商业）'!A:A,B13,'工程量计算式（商业）'!E:E) -> 8.9568 | E13: m2 | F13: =VLOOKUP(B13,'综合单价分析表（商业）'!A:I,9,) -> 1548.1117 | G13: =+F13*D13 -> 13866.127
A14: =MAX($A$3:$A13)+1 -> 11 | B14: 首层座槽式玻璃幕墙（10+1.9SGP+10Low-E(双银)+12A+10㎜全超白钢化夹层中空玻璃） | C14: 2#楼南立面18~23轴，9剖 | D14: =SUMIF('工程量计算式（商业）'!A:A,B14,'工程量计算式（商业）'!E:E) -> 54.9 | E14: m2 | F14: =VLOOKUP(B14,'综合单价分析表（商业）'!A:I,9,) -> 946.54305 | G14: =+F14*D14 -> 51965.214
A15: =MAX($A$3:$A14)+1 -> 12 | B15: 首层座槽式玻璃幕墙（10+1.9SGP+10Low-E(双银)+12A+10㎜全超白钢化夹层中空玻璃）（弯弧）（弧长1100㎜，圆弧半径900㎜，高3600㎜） | C15: 2#楼南立面18~23轴，9剖 | D15: =SUMIF('工程量计算式（商业）'!A:A,B15,'工程量计算式（商业）'!E:E) -> 3.96 | E15: m2 | F15: =VLOOKUP(B15,'综合单价分析表（商业）'!A:I,9,) -> 1645.2037 | G15: =+F15*D15 -> 6515.0066
A16: =MAX($A$3:$A15)+1 -> 13 | B16: 首层座槽式玻璃幕墙（10+1.9SGP+10Low-E(双银)+12A+10㎜全超白钢化夹层中空玻璃）（直+弯弧）（直段宽度600㎜+弧长1100㎜，圆弧半径700㎜，高3600㎜） | C16: 2#楼南立面18~23轴，9剖 | D16: =SUMIF('工程量计算式（商业）'!A:A,B16,'工程量计算式（商业）'!E:E) -> 6.12 | E16: m2 | F16: =VLOOKUP(B16,'综合单价分析表（商业）'!A:I,9,) -> 2336.0147 | G16: =+F16*D16 -> 14296.41
... A43: =MAX($A$3:$A42)+1 -> 40 | B43: 二层明框玻璃幕墙（6+1.52PVB+6Low-E(双银)+12A+10㎜全超白钢化夹层中空玻璃）（直+弯弧+直）（直段宽度210㎜+弧长1414㎜+直段宽度210㎜，圆弧半径900㎜，高2330㎜） | C43: 2#北立面23~18轴,2剖 | D43: =SUMIF('工程量计算式（商业）'!A:A,B43,'工程量计算式（商业）'!E:E) -> 8.54644 | E43: m2 | F43: =VLOOKUP(B43,'综合单价分析表（商业）'!A:I,9,) -> 1937.0646 | G43: =+F43*D43 -> 16555.006
A44: 二 | B44: 玻璃地弹门 | D44: =SUM(D45) -> 138.492 | G44: =SUM(G45) -> 145653.3
A45: 1 | B45: 地弹门（6Low-E(双银)+12A+6㎜全超白钢化中空玻璃） | D45: =SUMIF('工程量计算式（商业）'!A:A,B45,'工程量计算式（商业）'!E:E) -> 138.492 | E45: m2 | F45: =VLOOKUP(B45,'综合单价分析表（商业）'!A:I,9,) -> 1051.7091 | G45: =D45*F45 -> 145653.3 | H45: 无节点
A46: 三 | B46: 石材幕墙（2#商业有下沉庭院） | D46: =SUM(D47:D57) -> 862.11437 | G46: =SUM(G47:G57) -> 1414940.2
A47: 1 | B47: 30mm厚光面福鼎黑石材（造型柱基座） | D47: =SUMIF('工程量计算式（商业）'!A:A,B47,'工程量计算式（商业）'!E:E) -> 6.3 | E47: m2 | F47: =VLOOKUP(B47,'综合单价分析表（商业）'!A:I,9,) -> 1078.8613 | G47: =D47*F47 -> 6796.8263
A48: 2 | B48: 30mm厚光面贝金米黄石材 | D48: =SUMIF('工程量计算式（商业）'!A:A,B48,'工程量计算式（商业）'!E:E) -> 442.04052 | E48: m2 | F48: =VLOOKUP(B48,'综合单价分析表（商业）'!A:I,9,) -> 1281.9863 | G48: =D48*F48 -> 566689.88
A49: 3 | B49: 30mm厚光面贝金米黄石材（弧形） | D49: =D48*0.1 -> 44.204052 | E49: m2 | F49: =VLOOKUP(B49,'综合单价分析表（商业）'!A:I,9,) -> 4218.6373 | G49: =D49*F49 -> 186480.86
A50: 4 | B50: 25mm厚透光云石造型柱 | C50: 1#楼北立面24轴 | D50: =SUMIF('工程量计算式（商业）'!A:A,B50,'工程量计算式（商业）'!E:E) -> 13.6 | E50: m2 | F50: =VLOOKUP(B50,'综合单价分析表（商业）'!A:I,9,) -> 1097.1991 | G50: =D50*F50 -> 14921.908 | H50: =_xlfn.DISPIMG("ID_401A07236E3C452F939057EB265C2CEF",1) -> =DISPIMG("ID_401A07236E3C452F939057EB265C2CEF",1)
A51: 5 | B51: 30mm厚光面深灰色石材 | C51: 1#楼北立面15轴二层 | D51: =SUMIF('工程量计算式（商业）'!A:A,B51,'工程量计算式（商业）'!E:E) -> 7.833 | E51: m2 | F51: =VLOOKUP(B51,'综合单价分析表（商业）'!A:I,9,) -> 1216.3937 | G51: =D51*F51 -> 9528.0119
A52: 6 | B52: 40mm厚自然面贝金米黄石材 | C52: 2#楼北立面5/01轴至4/01轴交B轴至F轴内庭 | D52: =SUMIF('工程量计算式（商业）'!A:A,B52,'工程量计算式（商业）'!E:E) -> 23.3432 | E52: m2 | F52: =VLOOKUP(B52,'综合单价分析表（商业）'!A:I,9,) -> 1600.8976 | G52: =D52*F52 -> 37370.073
A53: 7 | B53: 40mm厚拉槽面贝金米黄石材 | C53: 2#楼北立面5/01轴至4/01轴交B轴至F轴内庭 | D53: =SUMIF('工程量计算式（商业）'!A:A,B53,'工程量计算式（商业）'!E:E) -> 176.0352 | E53: m2 | F53: =VLOOKUP(B53,'综合单价分析表（商业）'!A:I,9,) -> 1846.8711 | G53: =D53*F53 -> 325114.32
A54: 8 | B54: 30mm厚光面贝金米黄石材（造型柱弧形） | C54: 2#楼南立面1/01轴右侧柱子 | D54: =SUMIF('工程量计算式（商业）'!A:A,B54,'工程量计算式（商业）'!E:E) -> 30.828 | E54: m2 | F54: =VLOOKUP(B54,'综合单价分析表（商业）'!A:I,9,) -> 4132.5464 | G54: =D54*F54 -> 127398.14
A55: 9 | B55: 30mm厚透光云石（造型柱弧形） | C55: 2#楼南立面1/01轴右侧柱子 | D55: =SUMIF('工程量计算式（商业）'!A:A,B55,'工程量计算式（商业）'!E:E) -> 20.8104 | E55: m2 | F55: =VLOOKUP(B55,'综合单价分析表（商业）'!A:I,9,) -> 3481.0772 | G55: =D55*F55 -> 72442.61
A56: 10 | B56: 贝金米黄石材拉槽线条1 | C56: 1#楼南立面22轴至24轴，下沉庭院上部线条 | D56: =SUMIF('工程量计算式（商业）'!A:A,B56,'工程量计算式（商业）'!E:E) -> 48.56 | E56: 米 | F56: =VLOOKUP(B56,'综合单价分析表（商业）'!A:I,9,) -> 333.23904 | G56: =D56*F56 -> 16182.088
A57: 11 | B57: 贝金米黄石材拉槽线条2 | C57: 1#楼南立面22轴至24轴，下沉庭院下部弧形线条 | D57: =SUMIF('工程量计算式（商业）'!A:A,B57,'工程量计算式（商业）'!E:E) -> 48.56 | E57: 米 | F57: =VLOOKUP(B57,'综合单价分析表（商业）'!A:I,9,) -> 1071.1594 | G57: =D57*F57 -> 52015.5
A58: 四 | B58: 金属幕墙 | D58: =SUM(D59:D80) -> 4634.494 | G58: =SUM(G59:G80) -> 2867597.1 | J58: 工程量计算规则
A59: 1 | B59: 中灰色仿石材铝单板 | C59: 层间包梁，剖5 | D59: =SUMIF('工程量计算式（商业）'!A:A,B59,'工程量计算式（商业）'!E:E) -> 48.707275 | E59: m2 | F59: =VLOOKUP(B59,'综合单价分析表（商业）'!A:I,9,) -> 582.17204 | G59: =D59*F59 -> 28356.014
A60: 2 | B60: 中灰色仿石材铝单板（弧形） | D60: =SUMIF('工程量计算式（商业）'!A:A,B60,'工程量计算式（商业）'!E:E) -> 8.33553 | E60: m2 | F60: =VLOOKUP(B60,'综合单价分析表（商业）'!A:I,9,) -> 680.47326 | G60: =D60*F60 -> 5672.1053
A61: 3 | B61: 香槟色瓦楞板 | C61: 1.5㎜厚，层间包梁，剖5，JD-203 | D61: =SUMIF('工程量计算式（商业）'!A:A,B61,'工程量计算式（商业）'!E:E) -> 68.90185 | E61: m2 | F61: =VLOOKUP(B61,'综合单价分析表（商业）'!A:I,9,) -> 608.91521 | G61: =D61*F61 -> 41955.384
A62: 4 | B62: 香槟色瓦楞板（弧形） | D62: =SUMIF('工程量计算式（商业）'!A:A,B62,'工程量计算式（商业）'!E:E) -> 7.56828 | E62: m2 | F62: =VLOOKUP(B62,'综合单价分析表（商业）'!A:I,9,) -> 768.53397 | G62: =D62*F62 -> 5816.4803
A63: 5 | B63: 银灰色铝合金瓦楞板（异形） | C63: 北立面 | D63: =SUMIF('工程量计算式（商业）'!A:A,B63,'工程量计算式（商业）'!E:E) -> 39.45325 | E63: m2 | F63: =VLOOKUP(B63,'综合单价分析表（商业）'!A:I,9,) -> 976.3132 | G63: =D63*F63 -> 38518.729
A64: 6 | B64: 银灰色铝合金瓦楞板（异形）（弧形） | D64: =SUMIF('工程量计算式（商业）'!A:A,B64,'工程量计算式（商业）'!E:E) -> 6.183 | E64: m2 | F64: =VLOOKUP(B64,'综合单价分析表（商业）'!A:I,9,) -> 1216.4281 | G64: =D64*F64 -> 7521.1749
A65: 7 | B65: 中灰色铝单板 | D65: =SUMIF('工程量计算式（商业）'!A:A,B65,'工程量计算式（商业）'!E:E) -> 1.05 | E65: m2 | F65: =VLOOKUP(B65,'综合单价分析表（商业）'!A:I,9,) -> 650.75404 | G65: =D65*F65 -> 683.29174
A66: 8 | B66: 东立面墙面：银灰色铝板 | C66: 剖1，2#楼 | D66: =SUMIF('工程量计算式（商业）'!A:A,B66,'工程量计算式（商业）'!E:E) -> 171.44635 | E66: m2 | F66: =VLOOKUP(B66,'综合单价分析表（商业）'!A:I,9,) -> 705.15208 | G66: =D66*F66 -> 120895.75
...

Sheet 11#楼措施费
A1: 长住集团成都成华区迎晖路194号地块项目示范区幕墙工程
A2: 措施费清单
C3: 工程量 | D3: 单位 | E3: 综合单价 | F3: 合价 | G3: 备注
B4: 11#号楼 | E4: 不含增值税税额 | F4: 含增值税税额
A5: 1 | B5: 安全文明环境费（含幕墙施工时简易措施等） | C5: 1 | D5: 项 | E5: 20000 | F5: =E5*C5*$H$5 -> 21800 | H5: 1.09
A6: 2 | B6: 措施费（含脚手架、吊车设备、登高车、叉车等） | C6: =C5 -> 1 | D6: 项 | E6: =3688*25 -> 92200 | F6: =E6*C6*$H$5 -> 100498 | G6: 脚手架仅考虑改架、二次搭设等
A7: 3 | B7: 夜间施工、展示区赶工费（本项目工期较为紧张，充分考虑抢工费用，后续不可再向甲方上报抢工费用，存在夜间加班施工情况，本次报价充分考虑夜间加班费用） | C7: =C6 -> 1 | D7: 项 | E7: 10000 | F7: =E7*C7*$H$5 -> 10900 | G7: 仅仅11#楼考虑该费用，后续楼栋正常施工可以不计或少计取该费用
A8: 4 | B8: 二次搬运及多次搬运费 | C8: 1 | D8: 项 | E8: 10000 | F8: =E8*C8*$H$5 -> 10900 | G8: 材料比较复杂对场地要求较高，综合考虑肯定容易发生转运费用
A9: 5 | B9: 已完工程及设备保护费、成品保护费 | C9: =C8 -> 1 | D9: 项 | E9: 20000 | F9: =E9*C9*$H$5 -> 21800 | G9: 豪宅类项目成品保护费用偏高
A10: 7 | B10: 外墙清洗费 | C10: 1 | D10: 项 | E10: 12000 | F10: =E10*C10*$H$5 -> 13080
A11: 8 | B11: 开模费 | C11: 1 | D11: 项 | E11: 10000 | F11: =E11*C11*$H$5 -> 10900
A12: 合计 | F12: =SUM(F5:F11) -> 189878

Sheet 措施费 (商业)
A1: 长住集团成都成华区迎晖路194号地块项目示范区幕墙工程
A2: 措施费清单
C3: 工程量 | D3: 单位 | E3: 综合单价 | F3: 合价 | G3: 备注
B4: 1#2#楼商业幕墙 | E4: 不含增值税税额 | F4: 含增值税税额
A5: 1 | B5: 安全文明环境费 | C5: 1 | D5: 项 | E5: 5000 | F5: =E5*C5*$H$5 -> 5450 | H5: 1.09
A6: 2 | B6: 临时设施费 | C6: 1 | D6: 项 | E6: 0 | F6: =E6*C6*$H$5 -> 0
A7: 3 | B7: 夜间施工、展示区赶工费（本项目工期较为紧张，充分考虑抢工费用，后续不可再向甲方上报抢工费用，存在夜间加班施工情况，本次报价充分考虑夜间加班费用） | C7: 1 | D7: 项 | E7: 30000 | F7: =E7*C7*$H$5 -> 32700
A8: 4 | B8: 冬雨季施工增加费 | C8: 1 | D8: 项 | E8: 0 | F8: =E8*C8*$H$5 -> 0
A9: 5 | B9: 二次搬运及多次搬运费 | C9: 1 | D9: 项 | E9: 10000 | F9: =E9*C9*$H$5 -> 10900
A10: 6 | B10: 已完工程及设备保护费、成品保护费 | C10: 1 | D10: 项 | E10: 20000 | F10: =E10*C10*$H$5 -> 21800
A11: 7 | B11: 脚手架费 | C11: 1 | D11: 项 | E11: =K12 -> 96000 | F11: =E11*C11*$H$5 -> 104640 | K11: =3000*32 -> 96000
A12: 8 | B12: 吊篮费 | C12: 1 | D12: 项 | E12: 0 | F12: =E12*C12*$H$5 -> 0 | K12: =SUM(K11:K11) -> 96000
A13: 9 | B13: 机械措施费 | C13: 1 | D13: 项 | E13: 80000 | F13: =E13*C13*$H$5 -> 87200
A14: 12 | B14: 外墙清洗费 | C14: 1 | D14: 项 | E14: ='商业工程量清单 '!D104*2 -> 16638.821 | F14: =E14*C14*$H$5 -> 18136.315
A15: 13 | B15: 开模费 | C15: 1 | D15: 项 | E15: 50000 | F15: =E15*C15*$H$5 -> 54500
A16: 合计 | F16: =SUM(F5:F15) -> 335326.31

Sheet 综合单价分析表 (11#楼)
B1: 综合单价分析表
A2: 1 | B2: 序号 | C2: 清单项名称： | D2: =+A10 -> LMC6117G | F2: 80系列断桥隔热铝合金窗 | H2: 费率 | I2: 金额 | J2: 单位 | K2: =VLOOKUP(A2,排屋工程量清单!A:D,4,) -> 14.175
B3: 1 | C3: 直接工程费 | D3: 人工费 | I3: =J15 -> 80 | J3: 元 | L3: 80系列 | O3: 4.05 | P3: 1.75 | Q3: 1 | R3: =+Q3*P3*O3 -> 7.0875
B4: 2 | D4: 材料费 | I4: =J40 -> 651.84742 | J4: 元
B5: 3 | D5: 机械费 | I5: =J41 -> 10 | J5: 元 | M5: 名称 | N5: 米重 | O5: 长/宽 | P5: 数量 | Q5: 总重 | R5: 单方
B6: 4 | C6: 直接费 | D6: (1)+（2）+（3） | I6: =SUM(I3:I5) -> 741.84742 | J6: 元 | L6: 粉末喷涂铝型材T5 | M6: 铝合金窗框-竖 | O6: =P3 -> 1.75 | P6: 2 | Q6: =+P6*O6*N6 -> 0 | R6: =+Q6/R3 -> 0
B7: 5 | C7: 公司管理、利润 | D7: （4）*a% | H7: =+'材料表 '!$E$178 -> 0 | I7: =H7*I6 -> 0 | J7: 元 | L7: 粉末喷涂铝型材T5 | M7: 铝合金窗框-横 | O7: =O3 -> 4.05 | P7: 2 | Q7: =+P7*O7*N7 -> 0 | R7: =+Q7/R3 -> 0
B8: 6 | C8: 现场管理费 | D8: （4）*b% | H8: =+'材料表 '!$E$179 -> 0 | I8: =H8*I6 -> 0 | J8: 元 | L8: 粉末喷涂铝型材T5 | M8: 铝合金中梃-竖 | O8: =P3*2 -> 3.5 | P8: 1 | Q8: =+P8*O8*N8 -> 0 | R8: =+Q8/R3 -> 0
B9: 7 | C9: 税金 | D9: [(4)+(5)+(6)]*c% | H9: =+'材料表 '!$E$180 -> 0.09 | I9: =(I6+I7+I8)*H9 -> 66.766268 | J9: 元 | L9: 粉末喷涂铝型材T5 | M9: 铝合金加强中梃-竖 | O9: 0 | P9: 1 | Q9: =+P9*O9*N9 -> 0 | R9: =+Q9/R3 -> 0
A10: LMC6117G | B10: 8 | C10: 综合单价 | D10: （4）-（7）之和 | I10: =SUM(I6:I9) -> 808.61369 | J10: 元/m² | L10: 粉末喷涂铝型材T5 | M10: 铝合金中梃-横 | O10: 0 | P10: 1 | Q10: =+P10*O10*N10 -> 0 | R10: =+Q10/R3 -> 0
B11: 其中 | L11: 粉末喷涂铝型材T5 | M11: 铝合金转换料 | O11: =(P3*2+0.65*2)*2 -> 9.6 | P11: 1 | Q11: =+P11*O11*N11 -> 0 | R11: =+Q11/R3 -> 0
B12: 1 | C12: 人工费 | D12: 名称 | E12: 单位 | H12: 数量 | I12: 单价 | J12: 金额（元） | L12: 粉末喷涂铝型材T5 | M12: 铝合金扇料 | O12: =O11 -> 9.6 | P12: 1 | Q12: =+P12*O12*N12 -> 0 | R12: =+Q12/R3 -> 0
B13: 2 | D13: 80系列断桥隔热铝合金窗 | E13: ㎡ | H13: 1 | I13: =+辅材及安装费!$G$10 -> 80 | J13: =H13*I13 -> 80 | L13: 粉末喷涂铝型材T5 | M13: 开启压条 | O13: =O12 -> 9.6 | P13: 1 | Q13: =+P13*O13*N13 -> 0 | R13: =+Q13/R3 -> 0
B14: 3 | L14: 粉末喷涂铝型材T5 | M14: 固定压条 | O14: =2.75*2+P3*2 -> 9 | P14: 1 | Q14: =+P14*O14*N14 -> 0 | R14: =+Q14/R3 -> 0
B15: 4 | D15: 人工费合计 | E15: 元 | J15: =SUM(J13:J13) -> 80
B16: 1 | C16: 材料费 | D16: 粉末喷涂铝型材T6 | E16: =+VLOOKUP(D16,'材料表 '!C:F,2,0) -> kg | F16: =+SUMIF($L$3:$L$41,D16,$R$3:$R$41) -> 0 | G16: =+VLOOKUP(D16,'材料表 '!C:F,4,0) -> 0.03 | H16: =F16*(G16+1) -> 0 | I16: =+VLOOKUP(D16,'材料表 '!C:F,3,0) -> 25.849558 | J16: =H16*I16 -> 0 | K16: =H16*K2 -> 0
B17: 2 | D17: 粉末喷涂铝型材T5 | E17: =+VLOOKUP(D17,'材料表 '!C:F,2,0) -> kg | F17: 12 | G17: =+VLOOKUP(D17,'材料表 '!C:F,4,0) -> 0.03 | H17: =F17*(G17+1) -> 12.36 | I17: =+VLOOKUP(D17,'材料表 '!C:F,3,0) -> 25.672566 | J17: =H17*I17 -> 317.31292 | K17: =H17*K2 -> 175.203 | L17: 隔热条（H=39mm） | O17: =(O6*P6+O7*P7+O8*P8+O9*P9+O10*P10+O11*P11+O12*P12) -> 34.3 | P17: =+P6 -> 2 | Q17: =+P17*O17 -> 68.6 | R17: =+Q17/R3 -> 9.6790123
B18: 3 | D18: 阳极氧化铝型材T6 | E18: =+VLOOKUP(D18,'材料表 '!C:F,2,0) -> kg | F18: =+SUMIF($L$3:$L$41,D18,$R$3:$R$41) -> 0 | G18: =+VLOOKUP(D18,'材料表 '!C:F,4,0) -> 0.03 | H18: =F18*(G18+1) -> 0 | I18: =+VLOOKUP(D18,'材料表 '!C:F,3,0) -> 26.115044 | J18: =H18*I18 -> 0 | K18: =H18*K2 -> 0
B19: 4 | D19: 光身料铝型材T6 | E19: =+VLOOKUP(D19,'材料表 '!C:F,2,0) -> kg | F19: =+SUMIF($L$3:$L$41,D19,$R$3:$R$41) -> 0 | G19: =+VLOOKUP(D19,'材料表 '!C:F,4,0) -> 0.03 | H19: =F19*(G19+1) -> 0 | I19: =+VLOOKUP(D19,'材料表 '!C:F,3,0) -> 24.610619 | J19: =H19*I19 -> 0 | K19: =H19*K2 -> 0 | L19: 热镀锌钢管 | M19: 80*30*3 | N19: 4.898 | O19: =+O3*2+P3*2 -> 11.6 | P19: 1 | Q19: =+P19*O19*N19 -> 56.8168 | R19: =+Q19/R3 -> 8.0164797
B20: 5 | D20: 阳极氧化铝型材T5 | E20: =+VLOOKUP(D20,'材料表 '!C:F,2,0) -> kg | F20: =+SUMIF($L$3:$L$41,D20,$R$3:$R$41) -> 0 | G20: =+VLOOKUP(D20,'材料表 '!C:F,4,0) -> 0.03 | H20: =F20*(G20+1) -> 0 | I20: =+VLOOKUP(D20,'材料表 '!C:F,3,0) -> 26.115044 | J20: =H20*I20 -> 0 | K20: =H20*K2 -> 0 | R20: =+Q20/R3 -> 0
B21: 6 | D21: 铝材表面氟碳喷涂 | E21: =+VLOOKUP(D21,'材料表 '!C:F,2,0) -> m2 | F21: =+SUMIF($L$3:$L$41,D21,$R$3:$R$41) -> 0 | G21: =+VLOOKUP(D21,'材料表 '!C:F,4,0) -> 0 | H21: =F21*(G21+1) -> 0 | I21: =+VLOOKUP(D21,'材料表 '!C:F,3,0) -> 49.557522 | J21: =H21*I21 -> 0 | K21: =H21*K2 -> 0 | R21: =+Q28/R3 -> 0.23779894
B22: 7 | D22: 隔热条（H=39mm） | E22: =+VLOOKUP(D22,'材料表 '!C:F,2,0) -> m | F22: =+SUMIF($L$3:$L$41,D22,$R$3:$R$41) -> 9.6790123 | G22: =+VLOOKUP(D22,'材料表 '!C:F,4,0) -> 0 | H22: =F22*(G22+1) -> 9.6790123 | I22: =+VLOOKUP(D22,'材料表 '!C:F,3,0) -> 5.3097345 | J22: =H22*I22 -> 51.392986 | K22: =H22*K2 -> 137.2 | R22: =+Q29/R3 -> 0.59898413
B23: 8 | D23: 热镀锌钢管 | E23: =+VLOOKUP(D23,'材料表 '!C:F,2,0) -> kg | F23: =+SUMIF($L$3:$L$41,D23,$R$3:$R$41) -> 8.0164797 | G23: =+VLOOKUP(D23,'材料表 '!C:F,4,0) -> 0.03 | H23: =F23*(G23+1) -> 8.2569741 | I23: =+VLOOKUP(D23,'材料表 '!C:F,3,0) -> 3.8053097 | J23: =H23*I23 -> 31.420344 | K23: =H23*K2 -> 117.04261 | R23: =+Q23/R3 -> 0
B24: 9 | D24: 三元乙丙胶条 | E24: =+VLOOKUP(D24,'材料表 '!C:F,2,0) -> kg | F24: =0.065*1.3*(O12)*2/R3 -> 0.22891005 | G24: =+VLOOKUP(D24,'材料表 '!C:F,4,0) -> 0.03 | H24: =F24*(G24+1) -> 0.23577735 | I24: =+VLOOKUP(D24,'材料表 '!C:F,3,0) -> 19.469027 | J24: =H24*I24 -> 4.5903556 | K24: =H24*K2 -> 3.342144 | R24: =+Q24/R3 -> 0
B25: 10 | D25: 玻璃密封胶 | E25: =+VLOOKUP(D25,'材料表 '!C:F,2,0) -> 支 | F25: =0.8 -> 0.8 | G25: =+VLOOKUP(D25,'材料表 '!C:F,4,0) -> 0.15 | H25: =F25*(G25+1) -> 0.92 | I25: =+VLOOKUP(D25,'材料表 '!C:F,3,0) -> 11.504425 | J25: =H25*I25 -> 10.584071 | K25: =H25*K2 -> 13.041 | R25: =+Q25/R3 -> 0
B26: 11 | D26: 水泥砂浆封堵 | E26: =+VLOOKUP(D26,'材料表 '!C:F,2,0) -> m | F26: =(O3*2+P3*2)/R3 -> 1.6366843 | G26: =+VLOOKUP(D26,'材料表 '!C:F,4,0) -> 0 | H26: =F26*(G26+1) -> 1.6366843 | I26: =+VLOOKUP(D26,'材料表 '!C:F,3,0) -> 0 | J26: =H26*I26 -> 0 | K26: =H26*K2 -> 23.2 | R26: =+Q26/R3 -> 0
B27: 12 | D27: 外开窗五金件 | E27: =+VLOOKUP(D27,'材料表 '!C:F,2,0) -> 套 | F27: =2/R3 -> 0.28218695 | G27: =+VLOOKUP(D27,'材料表 '!C:F,4,0) -> 0 | H27: =F27*(G27+1) -> 0.28218695 | I27: =+VLOOKUP(D27,'材料表 '!C:F,3,0) -> 247.78761 | J27: =H27*I27 -> 69.92243 | K27: =H27*K2 -> 4
B28: 13 | D28: 5Low-E(双银)+12A+5+12A+5mm全超白钢化中空玻璃 | E28: =+VLOOKUP(D28,'材料表 '!C:F,2,0) -> m2 | F28: =+SUMIF($L$3:$L$41,D28,$R$3:$R$41) -> 0.23779894 | G28: =+VLOOKUP(D28,'材料表 '!C:F,4,0) -> 0.01 | H28: =F28*(G28+1) -> 0.24017693 | I28: =+VLOOKUP(D28,'材料表 '!C:F,3,0) -> 132.74336 | J28: =H28*I28 -> 31.881894 | K28: =H28*K2 -> 3.404508 | L28: 5Low-E(双银)+12A+5+12A+5mm全超白钢化中空玻璃 | N28: =(0.65-0.08-0.04)*(1.75-0.08*2) -> 0.8427 | P28: 2 | Q28: =N28*P28 -> 1.6854 | R28: =Q28/R3 -> 0.23779894
B29: 14 | D29: 10Low-E(双银)+12A+10+12A+10mm全超白钢化中空玻璃 | E29: =+VLOOKUP(D29,'材料表 '!C:F,2,0) -> m2 | F29: =+SUMIF($L$3:$L$41,D29,$R$3:$R$41) -> 0.59898413 | G29: =+VLOOKUP(D29,'材料表 '!C:F,4,0) -> 0.01 | H29: =F29*(G29+1) -> 0.60497397 | I29: =+VLOOKUP(D29,'材料表 '!C:F,3,0) -> 206.19469 | J29: =H29*I29 -> 124.74242 | K29: =H29*K2 -> 8.575506 | L29: 10Low-E(双银)+12A+10+12A+10mm全超白钢化中空玻璃 | N29: =(2.75-0.04-0.04)*(1.75-0.08*2) -> 4.2453 | P29: 1 | Q29: =N29*P29 -> 4.2453 | R29: =Q29/R3 -> 0.59898413
B30: 15
B31: 16
B32: 17
B33: 18
B34: 19
B35: 20
B36: 21
B37: 22
B38: 23
B39: 24 | D39: 辅材材料费 | E39: m2 | G39: 1 | H39: 1 | I39: =+辅材及安装费!$E$10 -> 10 | J39: =H39*I39 -> 10
B40: 25 | D40: 材料费合计 | J40: =SUM(J16:J39) -> 651.84742
...

Sheet 材料表 
A1: 材料表
A2: 序号 | B2: 分类 | C2: 项目名称 | D2: 单位 | E2: 不含税综合单价（元/单位） | F2: 材料损耗率 | G2: 备注 | I2: 含税单价 | K2: 11#楼 | L2: 1#2#商业
A3: 1 | B3: 石材 | C3: 25㎜葡萄牙灰石材 | D3: m2 | E3: =+I3/H3 -> 623.89381 | F3: 0.02 | H3: 1.13 | I3: =680+J4 -> 705 | J3: 加工增加费 | K3: =SUMIF('综合单价分析表 (11#楼)'!D:D,C3,'综合单价分析表 (11#楼)'!K:K) -> 366.63781 | L3: =SUMIF('综合单价分析表（商业）'!D:D,C3,'综合单价分析表（商业）'!K:K) -> 0
A4: =MAX($A$3:$A3)+1 -> 2 | C4: 25㎜葡萄牙灰石材（圆弧） | D4: m2 | E4: =+I4/H4 -> 1402.6549 | F4: 0.02 | H4: 1.13 | I4: =1560+J4 -> 1585 | J4: 25 | K4: =SUMIF('综合单价分析表 (11#楼)'!D:D,C4,'综合单价分析表 (11#楼)'!K:K) -> 54.888547 | L4: =SUMIF('综合单价分析表（商业）'!D:D,C4,'综合单价分析表（商业）'!K:K) -> 0
A5: =MAX($A$3:$A4)+1 -> 3 | C5: 25㎜葡萄牙米黄石材 | D5: m2 | E5: =+I5/H5 -> 358.40708 | F5: 0.02 | H5: 1.13 | I5: =380+J4 -> 405 | K5: =SUMIF('综合单价分析表 (11#楼)'!D:D,C5,'综合单价分析表 (11#楼)'!K:K) -> 134.7826 | L5: =SUMIF('综合单价分析表（商业）'!D:D,C5,'综合单价分析表（商业）'!K:K) -> 0
A6: =MAX($A$3:$A5)+1 -> 4 | C6: 25㎜葡萄牙米黄石材（圆弧） | D6: m2 | E6: =+I6/H6 -> 995.57522 | F6: 0.02 | H6: 1.13 | I6: =1100+J4 -> 1125 | K6: =SUMIF('综合单价分析表 (11#楼)'!D:D,C6,'综合单价分析表 (11#楼)'!K:K) -> 26.95652 | L6: =SUMIF('综合单价分析表（商业）'!D:D,C6,'综合单价分析表（商业）'!K:K) -> 0
A7: =MAX($A$3:$A6)+1 -> 5 | C7: 25㎜葡萄牙米黄石材线条 | D7: 米 | E7: =+I7/H7 -> 402.65487 | F7: 0.02 | H7: 1.13 | I7: =430+J4 -> 455 | K7: =SUMIF('综合单价分析表 (11#楼)'!D:D,C7,'综合单价分析表 (11#楼)'!K:K) -> 210.4032 | L7: =SUMIF('综合单价分析表（商业）'!D:D,C7,'综合单价分析表（商业）'!K:K) -> 0
A8: =MAX($A$3:$A7)+1 -> 6 | C8: 35㎜蓝眼睛石材（凹槽） | D8: m2 | E8: =+I8/H8 -> 535.39823 | F8: 0.05 | H8: 1.13 | I8: =580+J4 -> 605 | K8: =SUMIF('综合单价分析表 (11#楼)'!D:D,C8,'综合单价分析表 (11#楼)'!K:K) -> 123.69472 | L8: =SUMIF('综合单价分析表（商业）'!D:D,C8,'综合单价分析表（商业）'!K:K) -> 0
A9: =MAX($A$3:$A8)+1 -> 7 | C9: 35㎜蓝眼睛石材（凹槽）圆弧 | D9: m2 | E9: =+I9/H9 -> 1305.3097 | F9: 0.05 | H9: 1.13 | I9: =1450+J4 -> 1475 | K9: =SUMIF('综合单价分析表 (11#楼)'!D:D,C9,'综合单价分析表 (11#楼)'!K:K) -> 24.738945 | L9: =SUMIF('综合单价分析表（商业）'!D:D,C9,'综合单价分析表（商业）'!K:K) -> 0
A10: =MAX($A$3:$A9)+1 -> 8 | C10: 50㎜蓝眼睛石材（光面） | D10: m2 | E10: =+I10/H10 -> 774.33628 | F10: 0.02 | G10: 需确认厚度 | H10: 1.13 | I10: =850+J4 -> 875 | K10: =SUMIF('综合单价分析表 (11#楼)'!D:D,C10,'综合单价分析表 (11#楼)'!K:K) -> 3.758412 | L10: =SUMIF('综合单价分析表（商业）'!D:D,C10,'综合单价分析表（商业）'!K:K) -> 0
A11: 2 | C11: 30mm厚光面福鼎黑石材（造型柱基座） | D11: m2 | E11: =+I11/H11 -> 553.09735 | F11: 0.06 | G11: 带圆弧 | H11: 1.13 | I11: =600+J4 -> 625 | K11: =SUMIF('综合单价分析表 (11#楼)'!D:D,C11,'综合单价分析表 (11#楼)'!K:K) -> 0 | L11: =SUMIF('综合单价分析表（商业）'!D:D,C11,'综合单价分析表（商业）'!K:K) -> 12.978
A12: =MAX($A$3:$A11)+1 -> 9 | C12: 30mm厚光面贝金米黄石材 | D12: m2 | E12: =+I12/H12 -> 774.33628 | F12: 0.02 | H12: 1.13 | I12: =850+J4 -> 875 | K12: =SUMIF('综合单价分析表 (11#楼)'!D:D,C12,'综合单价分析表 (11#楼)'!K:K) -> 0 | L12: =SUMIF('综合单价分析表（商业）'!D:D,C12,'综合单价分析表（商业）'!K:K) -> 892.92185
A13: =MAX($A$3:$A12)+1 -> 10 | C13: 30mm厚光面贝金米黄石材（弧形） | D13: m2 | E13: =+I13/H13 -> 3119.469 | F13: 0.06 | H13: 1.13 | I13: =3500+J4 -> 3525 | K13: =SUMIF('综合单价分析表 (11#楼)'!D:D,C13,'综合单价分析表 (11#楼)'!K:K) -> 0 | L13: =SUMIF('综合单价分析表（商业）'!D:D,C13,'综合单价分析表（商业）'!K:K) -> 123.73803
A14: =MAX($A$3:$A13)+1 -> 11 | C14: 25mm厚透光云石造型柱 | D14: m2 | E14: =+I14/H14 -> 641.59292 | F14: 0.05 | H14: 1.13 | I14: =700+J4 -> 725 | K14: =SUMIF('综合单价分析表 (11#楼)'!D:D,C14,'综合单价分析表 (11#楼)'!K:K) -> 0 | L14: =SUMIF('综合单价分析表（商业）'!D:D,C14,'综合单价分析表（商业）'!K:K) -> 27.88
A15: =MAX($A$3:$A14)+1 -> 12 | C15: 30mm厚光面深灰色石材 | D15: m2 | E15: =+I15/H15 -> 623.89381 | F15: 0.02 | H15: 1.13 | I15: =680+J4 -> 705 | K15: =SUMIF('综合单价分析表 (11#楼)'!D:D,C15,'综合单价分析表 (11#楼)'!K:K) -> 0 | L15: =SUMIF('综合单价分析表（商业）'!D:D,C15,'综合单价分析表（商业）'!K:K) -> 15.82266
A16: =MAX($A$3:$A15)+1 -> 13 | C16: 40mm厚自然面贝金米黄石材 | D16: m2 | E16: =+I16/H16 -> 1084.0708 | F16: 0.02 | H16: 1.13 | I16: =1200+J4 -> 1225 | K16: =SUMIF('综合单价分析表 (11#楼)'!D:D,C16,'综合单价分析表 (11#楼)'!K:K) -> 0 | L16: =SUMIF('综合单价分析表（商业）'!D:D,C16,'综合单价分析表（商业）'!K:K) -> 47.153264
A17: =MAX($A$3:$A16)+1 -> 14 | C17: 40mm厚拉槽面贝金米黄石材 | D17: m2 | E17: =+I17/H17 -> 1305.3097 | F17: 0.02 | H17: 1.13 | I17: =1450+J4 -> 1475 | K17: =SUMIF('综合单价分析表 (11#楼)'!D:D,C17,'综合单价分析表 (11#楼)'!K:K) -> 0 | L17: =SUMIF('综合单价分析表（商业）'!D:D,C17,'综合单价分析表（商业）'!K:K) -> 355.5911
C18: 50㎜厚贝金米黄亚光面石材 | D18: m2 | E18: =+I18/H18 -> 1438.0531 | F18: 0.02 | H18: 1.13 | I18: =1600+J4 -> 1625
A19: =MAX($A$3:$A17)+1 -> 15 | C19: 30mm厚透光云石（造型柱弧形） | D19: m2 | E19: =+I19/H19 -> 840.70796 | F19: 0.02 | H19: 1.13 | I19: =I14+200+J4 -> 950 | K19: =SUMIF('综合单价分析表 (11#楼)'!D:D,C19,'综合单价分析表 (11#楼)'!K:K) -> 0 | L19: =SUMIF('综合单价分析表（商业）'!D:D,C19,'综合单价分析表（商业）'!K:K) -> 42.037008
A20: =MAX($A$3:$A19)+1 -> 16 | C20: 贝金米黄石材拉槽线条1 | D20: 米 | E20: =+I20/H20 -> 225.66372 | F20: 0.02 | G20: 75*77㎜ | H20: 1.13 | I20: =230+J4 -> 255 | K20: =SUMIF('综合单价分析表 (11#楼)'!D:D,C20,'综合单价分析表 (11#楼)'!K:K) -> 0 | L20: =SUMIF('综合单价分析表（商业）'!D:D,C20,'综合单价分析表（商业）'!K:K) -> 98.0912
A21: =MAX($A$3:$A20)+1 -> 17 | C21: 贝金米黄石材拉槽线条2 | D21: 米 | E21: =+I21/H21 -> 889.38053 | F21: 0.02 | G21: 200*200㎜，R=200 | H21: 1.13 | I21: =980+J4 -> 1005 | J21: 加工增加费 | K21: =SUMIF('综合单价分析表 (11#楼)'!D:D,C21,'综合单价分析表 (11#楼)'!K:K) -> 0 | L21: =SUMIF('综合单价分析表（商业）'!D:D,C21,'综合单价分析表（商业）'!K:K) -> 98.0912
A22: =MAX($A$3:$A21)+1 -> 18 | B22: 铝板 | C22: 2.5mm厚铝单板(香槟色) | D22: m2 | E22: =+I22/H22 -> 257.52212 | F22: 0.02 | H22: 1.13 | I22: =261+5+J22 -> 291 | J22: 25 | K22: =SUMIF('综合单价分析表 (11#楼)'!D:D,C22,'综合单价分析表 (11#楼)'!K:K) -> 10.05312 | L22: =SUMIF('综合单价分析表（商业）'!D:D,C22,'综合单价分析表（商业）'!K:K) -> 31.789192
A23: =MAX($A$3:$A22)+1 -> 19 | C23: 2.5mm厚铝单板 | D23: m2 | E23: =+I23/H23 -> 253.09735 | F23: 0.02 | H23: 1.13 | I23: =261+J22 -> 286 | K23: =SUMIF('综合单价分析表 (11#楼)'!D:D,C23,'综合单价分析表 (11#楼)'!K:K) -> 0 | L23: =SUMIF('综合单价分析表（商业）'!D:D,C23,'综合单价分析表（商业）'!K:K) -> 208.08
A24: =MAX($A$3:$A23)+1 -> 20 | C24: 2.5mm厚铝单板(浅灰色) | D24: m2 | E24: =+I24/H24 -> 253.09735 | F24: 0.02 | H24: 1.13 | I24: =261+J22 -> 286 | K24: =SUMIF('综合单价分析表 (11#楼)'!D:D,C24,'综合单价分析表 (11#楼)'!K:K) -> 287.29954 | L24: =SUMIF('综合单价分析表（商业）'!D:D,C24,'综合单价分析表（商业）'!K:K) -> 1479.1617
A25: =MAX($A$3:$A24)+1 -> 21 | C25: 2.5mm厚铝单板(浅灰色)弧形 | D25: m2 | E25: =+I25/H25 -> 261.9469 | F25: 0.02 | H25: 1.13 | I25: =261+10+J22 -> 296 | K25: =SUMIF('综合单价分析表 (11#楼)'!D:D,C25,'综合单价分析表 (11#楼)'!K:K) -> 3.7562633 | L25: =SUMIF('综合单价分析表（商业）'!D:D,C25,'综合单价分析表（商业）'!K:K) -> 0
A26: =MAX($A$3:$A25)+1 -> 22 | C26: 2.5mm厚铝单板(浅灰色)超长板 | D26: m2 | E26: =+I26/H26 -> 261.9469 | F26: 0.02 | G26: 屋面 | H26: 1.13 | I26: =261+10+J22 -> 296 | K26: =SUMIF('综合单价分析表 (11#楼)'!D:D,C26,'综合单价分析表 (11#楼)'!K:K) -> 350.97282 | L26: =SUMIF('综合单价分析表（商业）'!D:D,C26,'综合单价分析表（商业）'!K:K) -> 0
A27: =MAX($A$3:$A26)+1 -> 23 | C27: 2.5mm厚铝单板(浅灰色)超长板带圆弧 | D27: m2 | E27: =+I27/H27 -> 270.79646 | F27: 0.02 | G27: 北立面墙面 | H27: 1.13 | I27: =261+20+J22 -> 306 | K27: =SUMIF('综合单价分析表 (11#楼)'!D:D,C27,'综合单价分析表 (11#楼)'!K:K) -> 148.09678 | L27: =SUMIF('综合单价分析表（商业）'!D:D,C27,'综合单价分析表（商业）'!K:K) -> 0
A28: =MAX($A$3:$A27)+1 -> 24 | C28: 2.5mm厚铝单板(中灰色) | D28: m2 | E28: =+I28/H28 -> 253.09735 | F28: 0.02 | H28: 1.13 | I28: =261+J22 -> 286 | K28: =SUMIF('综合单价分析表 (11#楼)'!D:D,C28,'综合单价分析表 (11#楼)'!K:K) -> 186.68404 | L28: =SUMIF('综合单价分析表（商业）'!D:D,C28,'综合单价分析表（商业）'!K:K) -> 1.071
A29: =MAX($A$3:$A28)+1 -> 25 | C29: 2.5mm厚铝单板(浅灰色带弧形造型) | D29: m2 | E29: =+I29/H29 -> 270.79646 | F29: 0.02 | H29: 1.13 | I29: =261+20+J22 -> 306 | K29: =SUMIF('综合单价分析表 (11#楼)'!D:D,C29,'综合单价分析表 (11#楼)'!K:K) -> 124.22539 | L29: =SUMIF('综合单价分析表（商业）'!D:D,C29,'综合单价分析表（商业）'!K:K) -> 0
A30: =MAX($A$3:$A29)+1 -> 26 | C30: 2.5mm厚铝单板(银灰色) | D30: m2 | E30: =+I30/H30 -> 253.09735 | F30: 0.02 | H30: 1.13 | I30: =261+J22 -> 286 | K30: =SUMIF('综合单价分析表 (11#楼)'!D:D,C30,'综合单价分析表 (11#楼)'!K:K) -> 400.00402 | L30: =SUMIF('综合单价分析表（商业）'!D:D,C30,'综合单价分析表（商业）'!K:K) -> 1266.2836
A31: =MAX($A$3:$A30)+1 -> 27 | C31: 2.5mm厚铝单板(银灰色)弧形 | D31: m2 | E31: =+I31/H31 -> 261.9469 | F31: 0.02 | H31: 1.13 | I31: =261+10+J22 -> 296 | K31: =SUMIF('综合单价分析表 (11#楼)'!D:D,C31,'综合单价分析表 (11#楼)'!K:K) -> 45.291231 | L31: =SUMIF('综合单价分析表（商业）'!D:D,C31,'综合单价分析表（商业）'!K:K) -> 37.532573
A32: =MAX($A$3:$A31)+1 -> 28 | C32: 2.5mm厚铝单板(香槟色)弧形 | D32: m2 | E32: =+I32/H32 -> 266.37168 | F32: 0.02 | H32: 1.13 | I32: =261+5+10+J22 -> 301 | K32: =SUMIF('综合单价分析表 (11#楼)'!D:D,C32,'综合单价分析表 (11#楼)'!K:K) -> 1.945344 | L32: =SUMIF('综合单价分析表（商业）'!D:D,C32,'综合单价分析表（商业）'!K:K) -> 6.3578385
A33: =MAX($A$3:$A32)+1 -> 29 | C33: 2.5mm厚瓦楞铝板(浅灰色) | D33: m2 | E33: =+I33/H33 -> 319.46903 | F33: 0.02 | H33: 1.13 | I33: =336+J22 -> 361 | K33: =SUMIF('综合单价分析表 (11#楼)'!D:D,C33,'综合单价分析表 (11#楼)'!K:K) -> 5.6114662 | L33: =SUMIF('综合单价分析表（商业）'!D:D,C33,'综合单价分析表（商业）'!K:K) -> 0
A34: =MAX($A$3:$A33)+1 -> 30 | C34: 4mm厚穿孔铝单板(香槟色) | D34: m2 | E34: =+I34/H34 -> 361.06195 | F34: 0.02 | H34: 1.13 | I34: =373+10+J22 -> 408 | K34: =SUMIF('综合单价分析表 (11#楼)'!D:D,C34,'综合单价分析表 (11#楼)'!K:K) -> 258.12189 | L34: =SUMIF('综合单价分析表（商业）'!D:D,C34,'综合单价分析表（商业）'!K:K) -> 0
A35: =MAX($A$3:$A34)+1 -> 31 | C35: 4mm厚穿孔铝单板(香槟色)弧形 | D35: m2 | E35: =+I35/H35 -> 265.48673 | F35: 0.02 | H35: 1.13 | I35: 300 | K35: =SUMIF('综合单价分析表 (11#楼)'!D:D,C35,'综合单价分析表 (11#楼)'!K:K) -> 9.7279358 | L35: =SUMIF('综合单价分析表（商业）'!D:D,C35,'综合单价分析表（商业）'!K:K) -> 0
A36: =MAX($A$3:$A35)+1 -> 32 | C36: 2.5mm厚铝单板（中灰色/浅灰色双色) | D36: m2 | E36: =+I36/H36 -> 272.56637 | F36: 0.02 | H36: 1.13 | I36: =283+J22 -> 308 | K36: =SUMIF('综合单价分析表 (11#楼)'!D:D,C36,'综合单价分析表 (11#楼)'!K:K) -> 114.51041 | L36: =SUMIF('综合单价分析表（商业）'!D:D,C36,'综合单价分析表（商业）'!K:K) -> 0
A37: =MAX($A$3:$A36)+1 -> 33 | C37: 2.5mm厚铝单板（中灰色/浅灰色双色)弧形 | D37: m2 | E37: =+I37/H37 -> 281.41593 | F37: 0.02 | H37: 1.13 | I37: =283+10+J22 -> 318 | K37: =SUMIF('综合单价分析表 (11#楼)'!D:D,C37,'综合单价分析表 (11#楼)'!K:K) -> 5.5558384 | L37: =SUMIF('综合单价分析表（商业）'!D:D,C37,'综合单价分析表（商业）'!K:K) -> 0
A38: =MAX($A$3:$A37)+1 -> 34 | C38: 2.5mm厚蓝眼睛仿石铝板（带圆弧，带拉槽） | D38: m2 | E38: =+I38/H38 -> 270.79646 | F38: 0.02 | G38: 上下边带圆弧，带拉槽 | H38: 1.13 | I38: =261+10+10+J22 -> 306 | K38: =SUMIF('综合单价分析表 (11#楼)'!D:D,C38,'综合单价分析表 (11#楼)'!K:K) -> 88.53287 | L38: =SUMIF('综合单价分析表（商业）'!D:D,C38,'综合单价分析表（商业）'!K:K) -> 0
A39: =MAX($A$3:$A38)+1 -> 35 | C39: 2.5mm厚蓝眼睛仿石铝板（四边带圆弧） | D39: m2 | E39: =+I39/H39 -> 266.37168 | F39: 0.02 | G39: 上下边带圆弧，带拉槽 | H39: 1.13 | I39: =261+15+J22 -> 301 | K39: =SUMIF('综合单价分析表 (11#楼)'!D:D,C39,'综合单价分析表 (11#楼)'!K:K) -> 0 | L39: =SUMIF('综合单价分析表（商业）'!D:D,C39,'综合单价分析表（商业）'!K:K) -> 0
A40: =MAX($A$3:$A39)+1 -> 36 | C40: 2.5mm厚葡萄牙米黄仿石铝板（瓦楞板） | D40: m2 | E40: =+I40/H40 -> 287.61062 | F40: 0.02 | H40: 1.13 | I40: =300+J22 -> 325 | K40: =SUMIF('综合单价分析表 (11#楼)'!D:D,C40,'综合单价分析表 (11#楼)'!K:K) -> 179.05714 | L40: =SUMIF('综合单价分析表（商业）'!D:D,C40,'综合单价分析表（商业）'!K:K) -> 0
...

Sheet 工程量计算式 (11#楼)
A1: 名称 | B1: 位置 | C1: 单位 | D1: 计算式 | E1: 面积 | F1: 备注
A2: 石材幕墙 | E2: =SUM(E3:E32) -> 459.33362
A3: 25㎜葡萄牙灰石材 | B3: 西立面柱脚 | C3: ㎡ | D3: (0.55+0.45+0.15+2.9+0.15+2.9)*1 | E3: {=+EVALUATE(D3)} -> 7.1
A4: 25㎜葡萄牙灰石材 | B4: 南立面柱脚 | C4: ㎡ | D4: 0.55*(0.6+0.3)+0.55*(1.3+0.5+1.108+3.8+0.6+0.5+1.3)+0.55*(1.3+0.5+1.108+6.5+1.108+0.5+1.3)+0.55*(1.3+0.6) | E4: {=+EVALUATE(D4)} -> 13.3232
A5: 25㎜葡萄牙灰石材 | B5: 东立面柱脚 | C5: ㎡ | D5: 0.55*(4.95+0.15+2.9+0.15+2.9) | E5: {=+EVALUATE(D5)} -> 6.0775
A6: 25㎜葡萄牙灰石材 | B6: 北立面柱脚 | C6: ㎡ | D6: 0.55*0.6*4+0.25*（5.6+4.5+6.7+3.9+3.4+1+2+4.5+5.6） | E6: {=+EVALUATE(D6)} -> 10.62
A7: 25㎜葡萄牙灰石材 | B7: 一层采光井底部 | C7: ㎡ | D7: 0.2*5.11+0.2*5.86+0.2*5.01+0.2*2.46+0.2*1.96+0.2*5.36 | E7: {=+EVALUATE(D7)} -> 5.152
A8: 25㎜葡萄牙米黄石材 | B8: 西立面平板 | C8: ㎡ | D8: 1*3.06+3.5*1.53+0.45*3.06+2.87*0.2+2.87*(0.3+0.2)+2.9*3.06+2.1*3.5-2.7*1.7+0.75*2.1*2+0.75*3.5+(0.23+0.1)*2.88*2 | E8: {=+EVALUATE(D8)} -> 31.1108
A9: 25㎜葡萄牙米黄石材 | B9: 南立面平板 | C9: ㎡ | D9: 0.6*3.06*6+(1.3*2.18+0.65*0.25)*2+(1.3*2.18+0.65*0.25-0.9*1.97)*4+(0.23+0.25)*(10.5+7.85+10.5) | E9: {=+EVALUATE(D9)} -> 35.751
A10: 25㎜葡萄牙米黄石材 | B10: 东立面平板 | C10: ㎡ | D10: 2.9*3.06+4.95*3.06+(0.3+0.2)*2.87+(0.23+0.1)*2.88*2 | E10: {=+EVALUATE(D10)} -> 27.3568
A11: 25㎜葡萄牙米黄石材 | B11: 北立面平板 | C11: ㎡ | D11: 0.6*3.06*2+0.25*3.06*6+(0.6*3.06+1.2*0.23)*4+0.25*4.03*4+(0.25+0.23)*(11.1+6.7+8.3+4.1+11.1) | E11: {=+EVALUATE(D11)} -> 40.564
A12: 25㎜葡萄牙米黄石材线条 | B12: 西立面线条 | C12: 米 | D12: 10.73 | E12: {=+EVALUATE(D12)} -> 10.73
A13: 25㎜葡萄牙米黄石材线条 | B13: 南立面线条 | C13: 米 | D13: =11.7+9.1+11.7 -> 32.5 | E13: {=+EVALUATE(D13)} -> 32.5
A14: 25㎜葡萄牙米黄石材线条 | B14: 东立面线条 | C14: 米 | D14: 10.75 | E14: {=+EVALUATE(D14)} -> 10.75
A15: 25㎜葡萄牙米黄石材线条 | B15: 北立面线条 | C15: 米 | D15: =12.06+1.26+7.3+1.26+9.02+1.26+4.7+1.26+12.06 -> 50.18 | E15: {=+EVALUATE(D15)} -> 50.18
A16: 35㎜蓝眼睛石材（凹槽） | B16: 二层直段320高度 | C16: ㎡ | D16: (3.58+6.2+2.05+3.44+2.83+0.38+3.18+5.43+1.54+2.24+2.33+0.38+2.78+3.08+2.33+3.44+2.05+6.2+3.58)*(0.32+0.04*2) | E16: {=+EVALUATE(D16)} -> 22.816
A17: 35㎜蓝眼睛石材（凹槽） | B17: 二层弧段320高度 | C17: ㎡ | D17: (1.021*7+0.864*3)*(0.32+0.04*2) | E17: {=+EVALUATE(D17)} -> 3.8956
A18: 35㎜蓝眼睛石材（凹槽） | B18: 三层直段390高度 | C18: ㎡ | D18: (3.58+4.83+3.96+4.83+3.58)*(0.39+0.04*2) | E18: {=+EVALUATE(D18)} -> 9.7666
A19: 35㎜蓝眼睛石材（凹槽） | B19: 三层弧段390高度 | C19: ㎡ | D19: (1.021*2)*(0.39+0.04*2) | E19: {=+EVALUATE(D19)} -> 0.95974
A20: 35㎜蓝眼睛石材（凹槽） | B20: 三层直段560高度 | C20: ㎡ | D20: (1.61*3)*(0.56+0.04*2) | E20: {=+EVALUATE(D20)} -> 3.0912
A21: 35㎜蓝眼睛石材（凹槽） | B21: 四层直段470高度 | C21: ㎡ | D21: (2+2.8+1.63+2.8+1.63+1.63+2.8+2)*(0.47+0.04*2) | E21: {=+EVALUATE(D21)} -> 9.5095
A22: 35㎜蓝眼睛石材（凹槽） | B22: 四层弧段470高度 | C22: ㎡ | D22: (1.021*5)*(0.47+0.04*2) | E22: {=+EVALUATE(D22)} -> 2.80775
A23: 35㎜蓝眼睛石材（凹槽） | B23: 四层直段290高度 | C23: ㎡ | D23: (7.15+5.8+7.3)*(0.29+0.04*2) | E23: {=+EVALUATE(D23)} -> 7.4925
A24: 50㎜蓝眼睛石材（光面） | B24: 南立面 | C24: ㎡ | D24: 0.38*3.61+0.26*1.88 | E24: {=+EVALUATE(D24)} -> 1.8606
A25: 25㎜葡萄牙灰石材 | B25: 北立面采光天窗四周 | C25: ㎡ | D25: （1.35+0.4）*（0.4+0.15）*2+4.65*（0.4+0.15）-0.4*0.15*2 | E25: {=+EVALUATE(D25)} -> 4.3625
A26: 25㎜葡萄牙灰石材 | B26: 北立面采光天窗四周 | C26: ㎡ | D26: （1.35+0.4）*（0.4+0.15）*2+4.65*（0.54+0.15）-0.4*0.15*2 | E26: {=+EVALUATE(D26)} -> 5.0135
A27: 25㎜葡萄牙灰石材 | B27: 北立面采光天窗四周 | C27: ㎡ | D27: （1.35+0.4）*（0.4+0.15）*2+4.55*（0.54+0.15）-0.4*0.15*2 | E27: {=+EVALUATE(D27)} -> 4.9445
... A30: 25㎜葡萄牙灰石材 | B30: 北立面采光天窗四周 | C30: ㎡ | D30: （1.35+0.4）*（0.4+0.15）*2+4.9*（0.54+0.15）-0.4*0.15*2 | E30: {=+EVALUATE(D30)} -> 5.186
A31: 25㎜葡萄牙灰石材（下沉小院） | B31: 下沉小院 | C31: ㎡ | D31: 3.397*（0.46+0.37）+3.32*（0.46+0.37）+（2.418+6.555）+（11.789+5.024）+（2.355-6.75-1.912）+（2.25*2+0.3）*0.5+（2.25*2+0.85）*0.5 | E31: {=+EVALUATE(D31)*3} -> 90.38733 | F31: 3户
A33: 铝板幕墙 | E33: =SUM(E34:E115) -> 1865.4302
A34: 2.5㎜中灰色铝板1 | B34: 北立面幕窗上下口 | C34: ㎡ | D34: （4.05*（0.727）+6.2*0.21*4）*2+4.05*1 | E34: {=+EVALUATE(D34)} -> 20.3547
A35: 2.5㎜中灰色铝板1 | B35: 北立面幕窗上下口 | C35: ㎡ | D35: 2.55*0.727+5*0.21*4 | E35: {=+EVALUATE(D35)} -> 6.05385
A36: 2.5㎜中灰色铝板1 | B36: 北立面入户门上方 | C36: ㎡ | D36: 1*1.1*3 | E36: {=+EVALUATE(D36)} -> 3.3
A37: 2.5㎜中灰色铝板1 | B37: 北立面顶部穿孔铝单板上方 | C37: ㎡ | D37: （6.36+7.26+5.16+2.36+6.36）*0.139 | E37: {=+EVALUATE(D37)} -> 3.8225
A38: 2.5㎜浅灰色铝板3（一层墙面） | B38: 北立面18-15轴 | C38: ㎡ | D38: （11.1*2.75-5.25*0.524-4.05*1.75-1.0*2.75-6.2*0.524）+1.75*0.25*2+2.75*0.3*2 | E38: {=+EVALUATE(D38)} -> 17.2127
A39: 2.5㎜浅灰色铝板3（一层墙面） | B39: 北立面15-10轴 | C39: ㎡ | D39: （6.7*3.75-1.1*3.75*2）+2.75*0.3*4 | E39: {=+EVALUATE(D39)} -> 20.175
A40: 2.5㎜浅灰色铝板3（一层墙面） | B40: 北立面10-7轴 | C40: ㎡ | D40: （8.3*2.75-1.1*2.75-2.55*2.75-5.35*0.524）+2.75*0.3*2+2.75*0.25*2 | E40: {=+EVALUATE(D40)} -> 13.0091
A41: 2.5㎜浅灰色铝板3（一层墙面） | B41: 北立面7-4轴 | C41: ㎡ | D41: （4.1*3.75-1.1*3.75-2.3*0.524）+2.75*0.3*2 | E41: {=+EVALUATE(D41)} -> 11.6948
A42: 2.5㎜浅灰色铝板3（一层墙面） | B42: 北立面4-1轴 | C42: ㎡ | D42: （11.1*2.75-5.5*0.524-4.05*1.75-1.0*2.75）+0.75*0.25*2+2.75*0.3*2 | E42: {=+EVALUATE(D42)} -> 19.8305
A43: 2.5㎜浅灰色铝板2（带弧形造型） | B43: 北立面18-15轴 | C43: ㎡ | D43: （4.05+1.1）*1.578+（11.1-4.05-1.1）*1.338 | E43: {=+EVALUATE(D43)} -> 16.0878
...

Sheet 辅材及安装费
A1: 辅材及制作安装费
A2: 序号 | B2: 名称 | C2: 单位 | D2: 二次加工费 | E2: 辅材 | F2: 运输费用 | G2: 制作安装费 | H2: 合计
A3: 1 | B3: 铝板幕墙 | C3: 元/m2 | E3: 5 | F3: 5 | G3: 165 | H3: =+SUM(E3:G3) -> 175
A4: 2 | B4: 铝板幕墙-无龙骨 | C4: 元/m2 | E4: 5 | F4: 5 | G4: 68 | H4: =+SUM(E4:G4) -> 78
A5: 3 | B5: 幕墙式铝合窗 | C5: 元/m2 | D5: 40 | E5: 5 | F5: 5 | G5: 175 | H5: =+SUM(D5:G5) -> 225 | I5: 35
A6: 5 | B6: 玻璃栏杆 | C6: 元/m2 | E6: 10 | F6: 5 | G6: 135 | H6: =+SUM(E6:G6) -> 150
A7: 6 | B7: 格栅 | C7: 元/m2 | E7: 10 | F7: 5 | G7: =40+115 -> 155 | H7: =+SUM(E7:G7) -> 170
A8: 7 | B8: 石材幕墙 | C8: 元/m2 | D8: 12 | E8: 10 | F8: 5 | G8: 210 | H8: =+SUM(D8:G8) -> 237
A9: 8 | B9: 石材线条 | C9: 元/米 | E9: 2 | F9: 2 | G9: 25 | H9: =+SUM(E9:G9) -> 29
A10: 9 | B10: 80系列断桥隔热铝合金窗 | C10: 元/m2 | D10: 40 | E10: 10 | F10: 10 | G10: 80 | H10: =+SUM(D10:G10) -> 140
A11: 10 | B11: 铝合金百叶 | C11: 元/m2 | D11: 30 | E11: 10 | F11: 5 | G11: 65 | H11: =+SUM(D11:G11) -> 110
A12: 11 | B12: 铝合金线条 | C12: 元/米 | E12: 2 | F12: 1 | G12: 15 | H12: =+SUM(E12:G12) -> 18
A13: 12 | B13: 采光顶 | C13: 元/m2 | E13: 10 | F13: 5 | G13: =40+170 -> 210 | H13: =+SUM(E13:G13) -> 225
A14: 13 | B14: 防火隔断 | C14: 元/米 | E14: 2 | F14: 2 | G14: 25 | H14: =+SUM(E14:G14) -> 29
A15: 14 | B15: 镀锌铁皮封堵 | C15: 元/m2 | E15: 1 | F15: 1 | G15: 35 | H15: =+SUM(E15:G15) -> 37
A16: 15 | B16: 不锈钢天沟 | C16: 元/米 | E16: 5 | F16: 1 | G16: 130 | H16: =+SUM(E16:G16) -> 136
A17: 16 | B17: 座槽式玻璃幕墙 | C17: 元/m2 | E17: 10 | F17: 5 | G17: =20+170 -> 190 | H17: =+SUM(E17:G17) -> 205
A18: 17 | B18: T型钢玻璃幕墙 | C18: 元/m2 | E18: 10 | F18: 5 | G18: 180 | H18: =+SUM(E18:G18) -> 195
A19: 18 | B19: 明框玻璃幕墙 | C19: 元/m2 | E19: 10 | F19: 5 | G19: 170 | H19: =+SUM(E19:G19) -> 185
A20: 19 | B20: 金属网幕墙 | C20: 元/m2 | E20: 10 | F20: 5 | G20: 130 | H20: =+SUM(E20:G20) -> 145
A21: 20 | B21: 铝板背衬板 | C21: 元/m2 | E21: 5 | F21: 5 | G21: 35 | H21: =+SUM(E21:G21) -> 45

Sheet 措施
B1: 措施费
A2: 序号 | B2: 项目名称 | C2: 单位 | D2: 数量 | E2: 单价 | F2: 小计 | G2: 施工管理费、利润 | H2: 合价 | I2: 0 | L2: =88044/1000/6+6 -> 20.674
A3: 1 | B3: 防护棚 | C3: 项 | D3: 0 | E3: =+O70 -> 0 | F3: =D3*E3 -> 0 | G3: =F3*$I$2 -> 0 | H3: =F3+G3 -> 0 | I3: =+H3/$H$22 -> 0 | L3: 数量 | M3: 租期（月） | N3: 租赁费（元/月） | O3: 安拆（元/台） | P3: 进出运费（元/台） | Q3: 移位（元/台） | R3: 检测（元/台） | S3: 专家论证
A4: 2 | B4: 安全、文明施工费 | C4: 项 | D4: 0 | E4: 0 | F4: =D4*E4 -> 0 | G4: =F4*$I$2 -> 0 | H4: =F4+G4 -> 0 | I4: =+H4/$H$22 -> 0 | J4: 施工一段，高度≤100m | L4: 0 | M4: 4 | N4: =26*30 -> 780 | O4: 900 | P4: 200 | Q4: 550 | R4: 270 | S4: 0 | T4: =L4*(M4*N4+O4+P4+R4) -> 0
A5: 3 | B5: 临时设施费 | C5: 项 | D5: 0 | E5: 0 | F5: =D5*E5 -> 0 | G5: =F5*$I$2 -> 0 | H5: =F5+G5 -> 0 | I5: =+H5/$H$22 -> 0 | N5: =26*30 -> 780 | O5: 900 | P5: 200 | Q5: 550 | R5: 270 | T5: =L5*(M5*N5+O5+P5+Q5+R5) -> 0
A6: 4 | B6: 成品、半成品及设备保护费 | C6: m² | D6: 1 | E6: 1.5 | F6: =D6*E6 -> 1.5 | G6: =F6*$I$2 -> 0 | H6: =F6+G6 -> 1.5 | I6: =+H6/$H$22 -> 1.5304405e-05 | N6: =26*30 -> 780 | O6: 900 | P6: 200 | Q6: 550 | R6: 270 | T6: =L6*(M6*N6+O6+P6+Q6+R6) -> 0
A7: 5 | B7: 成品、半成品及设备堆放费 | C7: m² | D7: =+D6 -> 1 | E7: 1.5 | F7: =D7*E7 -> 1.5 | G7: =F7*$I$2 -> 0 | H7: =F7+G7 -> 1.5 | I7: =+H7/$H$22 -> 1.5304405e-05 | T7: =L7*(M7*N7+O7+P7+Q7+R7) -> 0
A8: 6 | B8: 幕墙清洗保洁费用(一次) | C8: m² | D8: =D6 -> 1 | E8: 2 | F8: =D8*E8 -> 2 | G8: =F8*$I$2 -> 0 | H8: =F8+G8 -> 2 | I8: =+H8/$H$22 -> 2.0405873e-05 | T8: =L8*(M8*N8+O8+P8+Q8+R8) -> 0
A9: 7 | B9: 二次搬运费 | C9: m² | D9: =D8 -> 1 | E9: 0 | F9: =D9*E9 -> 0 | G9: =F9*$I$2 -> 0 | H9: =F9+G9 -> 0 | I9: =+H9/$H$22 -> 0 | T9: =L9*(M9*N9+O9+P9+Q9+R9) -> 0
A10: 8 | B10: 垃圾清运费用 | C10: 项 | D10: =D9 -> 1 | E10: 1 | F10: =D10*E10 -> 1 | G10: =F10*$I$2 -> 0 | H10: =F10+G10 -> 1 | I10: =+H10/$H$22 -> 1.0202936e-05 | T10: =SUM(S4:T9) -> 0
A11: 9 | B11: 国标四性检测 | C11: 项 | D11: 1 | E11: 20000 | F11: =D11*E11 -> 20000 | G11: =F11*$I$2 -> 0 | H11: =F11+G11 -> 20000 | I11: =+H11/$H$22 -> 0.20405873 | L11: 数量 | M11: 单价
A12: 10 | B12: 防雷接地 | C12: m² | D12: =D6 -> 1 | E12: 1 | F12: =D12*E12 -> 1 | G12: =F12*$I$2 -> 0 | H12: =F12+G12 -> 1 | I12: =+H12/$H$22 -> 1.0202936e-05 | K12: 双排 | L12: =125000/1000*16 -> 2000 | M12: 35 | N12: =L12*M12 -> 70000
A13: 11 | B13: 淋水试验（二次） | C13: m² | D13: =+D12 -> 1 | E13: 1.5 | F13: =D13*E13 -> 1.5 | G13: =F13*$I$2 -> 0 | H13: =F13+G13 -> 1.5 | I13: =+H13/$H$22 -> 1.5304405e-05 | K13: 满堂 | L13: =+T16 -> 0 | M13: 17 | N13: =L13*M13 -> 0
A14: 12 | B14: 措施费(吊篮、脚手架) | C14: 项 | D14: 1 | E14: =T10+N12+N13 -> 70000 | F14: =D14*E14 -> 70000 | G14: =F14*$I$2 -> 0 | H14: =F14+G14 -> 70000 | I14: =+H14/$H$22 -> 0.71420555
A15: 13 | B15: 剪刀车、直臂车 | C15: 项 | D15: 1 | E15: 3000 | F15: =D15*E15 -> 3000 | G15: =F15*$I$2 -> 0 | H15: =F15+G15 -> 3000 | I15: =+H15/$H$22 -> 0.030608809
A16: 14 | B16: 开模费 | C16: 项 | D16: 0 | E16: 0 | F16: =D16*E16 -> 0 | G16: =F16*$I$2 -> 0 | H16: =F16+G16 -> 0 | I16: =+H16/$H$22 -> 0
A17: 15 | B17: 水电费 | C17: m² | D17: =+D12 -> 1 | E17: 1.5 | F17: =D17*E17 -> 1.5 | G17: =F17*$I$2 -> 0 | H17: =F17+G17 -> 1.5 | I17: =+H17/$H$22 -> 1.5304405e-05
A18: 16 | B18: 住宿费 | C18: m² | D18: =+D17 -> 1 | E18: 1 | F18: =D18*E18 -> 1 | G18: =F18*$I$2 -> 0 | H18: =F18+G18 -> 1 | I18: =+H18/$H$22 -> 1.0202936e-05
A19: 17 | B19: 专家论证费 | C19: 项 | D19: 1 | E19: 5000 | F19: =D19*E19 -> 5000 | G19: =F19*$I$2 -> 0 | H19: =F19+G19 -> 5000 | I19: =+H19/$H$22 -> 0.051014682
A20: 18 | B20: 施工许可证 | C20: 项 | D20: 1 | F20: =D20*E20 -> 0 | G20: =F20*$I$2 -> 0 | H20: =F20+G20 -> 0 | I20: =+H20/$H$22 -> 0
A21: 19 | B21: 设计费 | C21: 项 | D21: 1 | E21: 0 | F21: =D21*E21 -> 0 | G21: =F21*$I$2 -> 0 | H21: =F21+G21 -> 0 | I21: =+H21/$H$22 -> 0
A22: 20 | B22: 不含税小计 | H22: =SUM(H3:H21) -> 98011
H23: =H22/D18 -> 98011
G86: 120*60*5 | H86: 13.345 | I86: 0.77 | J86: 1 | K86: =+J86*I86*H86 -> 10.27565 | L86: 3.9115044 | M86: =+L86*K86 -> 40.19325
G87: 100*50*5 | H87: 10.99 | I87: 0.25 | J87: 2 | K87: =+J87*I87*H87 -> 5.495 | L87: 3.9115044 | M87: =+L87*K87 -> 21.493717
G88: 300*200*10 | H88: =0.3*0.2*10*7.85 -> 4.71 | I88: 1 | J88: 2 | K88: =+J88*I88*H88 -> 9.42 | L88: 5.1327434 | M88: =+L88*K88 -> 48.350442
G89: 加劲板 | H89: 1.01 | I89: 2 | J89: 2 | K89: =+J89*I89*H89 -> 4.04 | L89: 5.1327434 | M89: =+L89*K89 -> 20.736283
G90: 螺栓 | K90: =+J88*I88*4 -> 8 | L90: 1.9469027 | M90: =+L90*K90 -> 15.575221
L91: 材料费 | M91: =SUM(M86:M90) -> 146.34891
L92: 安装费 | M92: 80
M93: =SUM(M91:M92) -> 226.34891

Sheet 综合单价分析表（商业）
B1: 综合单价分析表
A2: 1 | B2: 序号 | C2: 清单项名称： | D2: =+A10 -> 首层座槽式玻璃幕墙（15+2.25SGP+15㎜全超白钢化夹层玻璃）（超宽） | F2: 玻璃幕墙 | H2: 费率 | I2: 金额 | J2: 单位 | K2: =VLOOKUP(A2,'商业工程量清单 '!$A$4:$D$44,4,FALSE) -> 25.92
B3: 1 | C3: 直接工程费 | D3: 人工费 | I3: =J15 -> 210 | J3: 元 | L3: 1#楼南立面 | M3: 16剖 | O3: 7.2 | P3: 3.6 | Q3: 1 | R3: =+Q3*P3*O3 -> 25.92
B4: 2 | D4: 材料费 | I4: =J42 -> 1437.136 | J4: 元
B5: 3 | D5: 机械费 | I5: =J43 -> 5 | J5: 元 | M5: 名称 | N5: 米重 | O5: 长/宽 | P5: 数量 | Q5: 总重 | R5: 单方
B6: 4 | C6: 直接费 | D6: (1)+（2）+（3） | I6: =SUM(I3:I5) -> 1652.136 | J6: 元 | L6: 粉末喷涂铝型材T6 | M6: 铝合金立柱 | N6: 3.111 | O6: =P3 -> 3.6 | P6: 1 | Q6: =+P6*O6*N6 -> 11.1996 | R6: =+Q6/R3 -> 0.43208333
B7: 5 | C7: 公司管理、利润 | D7: （4）*a% | H7: =+'材料表 '!$E$178 -> 0 | I7: =H7*I6 -> 0 | J7: 元 | L7: 阳极氧化铝型材T5 | M7: 铝合金副框 | N7: 0.507 | O7: =O6*2 -> 7.2 | P7: 1 | Q7: =+P7*O7*N7 -> 3.6504 | R7: =+Q7/R3 -> 0.14083333
B8: 6 | C8: 现场管理费 | D8: （4）*b% | H8: =+'材料表 '!$E$179 -> 0 | I8: =H8*I6 -> 0 | J8: 元 | L8: 阳极氧化铝型材T6 | M8: 铝合金压块 | N8: 0.499 | O8: =P3/0.3*0.05 -> 0.6 | P8: 1 | Q8: =+P8*O8*N8 -> 0.2994 | R8: =+Q8/R3 -> 0.011550926
B9: 7 | C9: 税金 | D9: [(4)+(5)+(6)]*c% | H9: =+'材料表 '!$E$180 -> 0.09 | I9: =(I6+I7+I8)*H9 -> 148.69224 | J9: 元 | L9: 阳极氧化铝型材T6 | M9: 立柱插芯 | N9: =2.9 -> 2.9 | O9: 0.2 | P9: 1 | Q9: =+P9*O9*N9 -> 0.58 | R9: =+Q9/R3 -> 0.022376543
A10: 首层座槽式玻璃幕墙（15+2.25SGP+15㎜全超白钢化夹层玻璃）（超宽） | B10: 8 | C10: 综合单价 | D10: （4）-（7）之和 | I10: =SUM(I6:I9) -> 1800.8283 | J10: 元/m² | L10: 阳极氧化铝型材T6 | P10: 1 | Q10: =+P10*O10*N10 -> 0 | R10: =+Q10/R3 -> 0
B11: 其中 | L11: 光身料铝型材T5 | P11: 1 | Q11: =+P11*O11*N11 -> 0 | R11: =+Q11/R3 -> 0
B12: 1 | C12: 人工费 | D12: 名称 | E12: 单位 | H12: 数量 | I12: 单价 | J12: 金额（元） | L12: 粉末喷涂铝型材T5 | P12: 1 | Q12: =+P12*O12*N12 -> 0 | R12: =+Q12/R3 -> 0
B13: 2 | D13: 座槽式玻璃幕墙 | E13: ㎡ | H13: 1 | I13: =+辅材及安装费!$G$17+20 -> 210 | J13: =H13*I13 -> 210 | L13: 粉末喷涂铝型材T6 | P13: 1 | Q13: =+P13*O13*N13 -> 0 | R13: =+Q13/R3 -> 0
B14: 3 | P14: 1 | Q14: =+P14*O14*N14 -> 0 | R14: =+Q14/R3 -> 0
B15: 4 | D15: 人工费合计 | E15: 元 | J15: =SUM(J13:J13) -> 210 | P15: 1
B16: 1 | C16: 材料费 | D16: 粉末喷涂铝型材T6 | E16: =+VLOOKUP(D16,'材料表 '!C:F,2,0) -> kg | F16: =+SUMIF($L$3:$L$43,D16,$R$3:$R$43) -> 0.43208333 | G16: =+VLOOKUP(D16,'材料表 '!C:F,4,0) -> 0.03 | H16: =F16*(G16+1) -> 0.44504583 | I16: =+VLOOKUP(D16,'材料表 '!C:F,3,0) -> 25.849558 | J16: =H16*I16 -> 11.504238 | K16: =H16*K2 -> 11.535588 | P16: 1
B17: 2 | D17: 粉末喷涂铝型材T5 | E17: =+VLOOKUP(D17,'材料表 '!C:F,2,0) -> kg | F17: =+SUMIF($L$3:$L$43,D17,$R$3:$R$43) -> 0 | G17: =+VLOOKUP(D17,'材料表 '!C:F,4,0) -> 0.03 | H17: =F17*(G17+1) -> 0 | I17: =+VLOOKUP(D17,'材料表 '!C:F,3,0) -> 25.672566 | J17: =H17*I17 -> 0 | K17: =H17*K2 -> 0
B18: 3 | D18: 阳极氧化铝型材T5 | E18: =+VLOOKUP(D18,'材料表 '!C:F,2,0) -> kg | F18: =+SUMIF($L$3:$L$43,D18,$R$3:$R$43) -> 0.14083333 | G18: =+VLOOKUP(D18,'材料表 '!C:F,4,0) -> 0.03 | H18: =F18*(G18+1) -> 0.14505833 | I18: =+VLOOKUP(D18,'材料表 '!C:F,3,0) -> 26.115044 | J18: =H18*I18 -> 3.7882048 | K18: =H18*K2 -> 3.759912
B19: 4 | D19: 阳极氧化铝型材T6 | E19: =+VLOOKUP(D19,'材料表 '!C:F,2,0) -> kg | F19: =+SUMIF($L$3:$L$43,D19,$R$3:$R$43) -> 0.033927469 | G19: =+VLOOKUP(D19,'材料表 '!C:F,4,0) -> 0.03 | H19: =F19*(G19+1) -> 0.034945293 | I19: =+VLOOKUP(D19,'材料表 '!C:F,3,0) -> 26.115044 | J19: =H19*I19 -> 0.91259788 | K19: =H19*K2 -> 0.905782 | L19: 隔热条（H=39mm） | O19: =(O6*P6) -> 3.6 | P19: 1 | Q19: =+P19*O19 -> 3.6 | R19: =+Q19/R3 -> 0.13888889
B20: 5 | D20: 光身料铝型材T5 | E20: =+VLOOKUP(D20,'材料表 '!C:F,2,0) -> kg | F20: =+SUMIF($L$3:$L$43,D20,$R$3:$R$43) -> 0 | G20: =+VLOOKUP(D20,'材料表 '!C:F,4,0) -> 0.03 | H20: =F20*(G20+1) -> 0 | I20: =+VLOOKUP(D20,'材料表 '!C:F,3,0) -> 24.433628 | J20: =H20*I20 -> 0 | K20: =H20*K2 -> 0
B21: 6 | D21: 铝材表面氟碳喷涂 | E21: =+VLOOKUP(D21,'材料表 '!C:F,2,0) -> m2 | F21: =+SUMIF($L$3:$L$43,D21,$R$3:$R$43) -> 0 | G21: =+VLOOKUP(D21,'材料表 '!C:F,4,0) -> 0 | H21: =F21*(G21+1) -> 0 | I21: =+VLOOKUP(D21,'材料表 '!C:F,3,0) -> 49.557522 | J21: =H21*I21 -> 0 | K21: =H21*K2 -> 0 | L21: 热镀锌埋件 | M21: （200+120）*300*8 | N21: =0.32*0.3*8*7.85 -> 6.0288 | O21: 2 | P21: 1 | Q21: =+P21*O21*N21 -> 12.0576 | R21: =+Q21/R3 -> 0.46518519
B22: 7 | K22: =H22*K2 -> 0 | L22: 热镀锌钢连接件 | M22: L=130，100*63*8角钢 | N22: 9.88 | O22: =0.13 -> 0.13 | P22: 4 | Q22: =+P22*O22*N22 -> 5.1376 | R22: =Q22/R3 -> 0.19820988
B23: 8 | D23: 热镀锌钢管 | E23: =+VLOOKUP(D23,'材料表 '!C:F,2,0) -> kg | F23: =+SUMIF($L$3:$L$43,D23,$R$3:$R$43) -> 0 | G23: =+VLOOKUP(D23,'材料表 '!C:F,4,0) -> 0.03 | H23: =F23*(G23+1) -> 0 | I23: =+VLOOKUP(D23,'材料表 '!C:F,3,0) -> 3.8053097 | J23: =H23*I23 -> 0 | K23: =H23*K2 -> 0 | L23: M12化学锚栓 | O23: 6 | P23: =O21*P21 -> 2 | Q23: =O23*P23 -> 12 | R23: =Q23/R3 -> 0.46296296
B24: 9 | D24: 热镀锌角钢 | E24: =+VLOOKUP(D24,'材料表 '!C:F,2,0) -> kg | F24: =+SUMIF($L$3:$L$43,D24,$R$3:$R$43) -> 0 | G24: =+VLOOKUP(D24,'材料表 '!C:F,4,0) -> 0.03 | H24: =F24*(G24+1) -> 0 | I24: =+VLOOKUP(D24,'材料表 '!C:F,3,0) -> 3.539823 | J24: =H24*I24 -> 0 | K24: =H24*K2 -> 0 | L24: M12x120不锈钢螺栓 | O24: 2 | P24: 2 | Q24: =O24*P24 -> 4 | R24: =Q24/R3 -> 0.15432099
B25: 10 | D25: 三元乙丙胶条 | E25: =+VLOOKUP(D25,'材料表 '!C:F,2,0) -> kg | F25: =+SUMIF($L$3:$L$43,D25,$R$3:$R$43) -> 0 | G25: =+VLOOKUP(D25,'材料表 '!C:F,4,0) -> 0.03 | H25: =F25*(G25+1) -> 0 | I25: =+VLOOKUP(D25,'材料表 '!C:F,3,0) -> 19.469027 | J25: =H25*I25 -> 0 | K25: =H25*K2 -> 0 | L25: 热镀锌钢连接件 | N25: =(0.058+0.04*2)*5*7.85 -> 5.4165 | O25: =O3 -> 7.2 | P25: 1 | Q25: =+P25*O25*N25 -> 38.9988 | R25: =+Q25/R3 -> 1.5045833
B26: 11 | D26: 热镀锌埋件 | E26: =+VLOOKUP(D26,'材料表 '!C:F,2,0) -> kg | F26: =+SUMIF($L$3:$L$43,D26,$R$3:$R$43) -> 0.46518519 | G26: =+VLOOKUP(D26,'材料表 '!C:F,4,0) -> 0.03 | H26: =F26*(G26+1) -> 0.47914074 | I26: =+VLOOKUP(D26,'材料表 '!C:F,3,0) -> 6.0176991 | J26: =H26*I26 -> 2.8833248 | K26: =H26*K2 -> 12.419328 | L26: 热镀锌角钢
B27: 12 | D27: 热镀锌钢连接件 | E27: =+VLOOKUP(D27,'材料表 '!C:F,2,0) -> kg | F27: =+SUMIF($L$3:$L$43,D27,$R$3:$R$43) -> 1.7027932 | G27: =+VLOOKUP(D27,'材料表 '!C:F,4,0) -> 0.03 | H27: =F27*(G27+1) -> 1.753877 | I27: =+VLOOKUP(D27,'材料表 '!C:F,3,0) -> 6.0176991 | J27: =H27*I27 -> 10.554304 | K27: =H27*K2 -> 45.460492
B28: 13 | D28: M12化学锚栓 | E28: =+VLOOKUP(D28,'材料表 '!C:F,2,0) -> 套 | F28: =+SUMIF($L$3:$L$43,D28,$R$3:$R$43) -> 0.46296296 | G28: =+VLOOKUP(D28,'材料表 '!C:F,4,0) -> 0 | H28: =F28*(G28+1) -> 0.46296296 | I28: =+VLOOKUP(D28,'材料表 '!C:F,3,0) -> 2.2123894 | J28: =H28*I28 -> 1.0242543 | K28: =H28*K2 -> 12
B29: 14 | D29: M12x120不锈钢螺栓 | E29: =+VLOOKUP(D29,'材料表 '!C:F,2,0) -> 套 | F29: =+SUMIF($L$3:$L$43,D29,$R$3:$R$43) -> 0.15432099 | G29: =+VLOOKUP(D29,'材料表 '!C:F,4,0) -> 0 | H29: =F29*(G29+1) -> 0.15432099 | I29: =+VLOOKUP(D29,'材料表 '!C:F,3,0) -> 2.4778761 | J29: =H29*I29 -> 0.38238829 | K29: =H29*K2 -> 4
B30: 15 | D30: 耐候密封胶 | E30: =+VLOOKUP(D30,'材料表 '!C:F,2,0) -> 支 | F30: =8*8*(O3*4+P3*4)/500/R3+16*32*(P3)/500/R3 -> 0.35555556 | G30: =+VLOOKUP(D30,'材料表 '!C:F,4,0) -> 0.15 | H30: =F30*(G30+1) -> 0.40888889 | I30: =+VLOOKUP(D30,'材料表 '!C:F,3,0) -> 11.504425 | J30: =H30*I30 -> 4.7040315 | K30: =H30*K2 -> 10.5984
B31: 16 | D31: 耐候结构胶 | E31: =+VLOOKUP(D31,'材料表 '!C:F,2,0) -> 支 | F31: =16*8*(P3*P6)*2/500/R3 -> 0.071111111 | G31: =+VLOOKUP(D31,'材料表 '!C:F,4,0) -> 0.15 | H31: =F31*(G31+1) -> 0.081777778 | I31: =+VLOOKUP(D31,'材料表 '!C:F,3,0) -> 14.159292 | J31: =H31*I31 -> 1.1579154 | K31: =H31*K2 -> 2.11968
B32: 17 | K32: =H32*K2 -> 0
B33: 18 | K33: =H33*K2 -> 0
B34: 19 | D34: 15+2.28SGP+15全超白钢化夹层玻璃(超宽)（宽7200㎜，高3600㎜） | E34: =+VLOOKUP(D34,'材料表 '!C:F,2,0) -> m2 | F34: 1.01 | G34: =+VLOOKUP(D34,'材料表 '!C:F,4,0) -> 0.01 | H34: =F34*(G34+1) -> 1.0201 | I34: =+VLOOKUP(D34,'材料表 '!C:F,3,0) -> 1362.8319 | J34: =H34*I34 -> 1390.2248 | K34: =H34*K2 -> 26.440992
B35: 20 | K35: =H35*K2 -> 0
B36: 21 | K36: =H36*K2 -> 0
B37: 22 | K37: =H37*K2 -> 0
B38: 23 | K38: =H38*K2 -> 0
B39: 24 | K39: =H39*K2 -> 0
B40: 25
...

Sheet 工程量计算式（商业）
A1: 名称 | B1: 位置 | C1: 单位 | D1: 计算式 | E1: 面积 | F1: 备注
A2: 玻璃幕墙 | E2: =SUM(E3:E56) -> 1528.5488
A3: 首层座槽式玻璃幕墙（15+2.25SGP+15㎜全超白钢化夹层玻璃）（超宽） | B3: 1#楼南立面2/01~1/01轴 | C3: ㎡ | D3: 7.2*3.6 | E3: {=+EVALUATE(D3)} -> 25.92 | F3: 1#
A4: 首层座槽式玻璃幕墙（12Low-E(双银)+12A+12全超白钢化中空玻璃） | B4: 1#楼南立面1~2轴 | C4: ㎡ | D4: （1.85+1.2）*3.6 | E4: {=+EVALUATE(D4)} -> 10.98 | F4: 1#
A5: 首层座槽式玻璃幕墙（12Low-E(双银)+12A+12全超白钢化中空玻璃）（直+弯弧）（直段宽度300㎜+弧长942㎜，圆弧半径600㎜，高3600㎜） | B5: 1#楼南立面2/01~1/01轴 | C5: ㎡ | D5: （0.942+0.3）*2*3.6 | E5: {=+EVALUATE(D5)} -> 8.9424 | F5: 1#
A6: 首层座槽式玻璃幕墙（12+1.9SGP+12㎜全超白钢化夹层玻璃） | B6: 1#楼南立面2~22轴 | C6: ㎡ | D6: （1.4*2+30.8+3.9+0.22+1.05*2+5.8）*3.6 | E6: {=+EVALUATE(D6)} -> 164.232 | F6: 1#
A7: 首层座槽式玻璃幕墙（12+1.9SGP+12㎜全超白钢化夹层玻璃）（弯弧）（弧长1414㎜，圆弧半径900㎜，高3600㎜） | B7: 1#楼南立面2~22轴 | C7: ㎡ | D7: （1.414*4）*3.6 | E7: {=+EVALUATE(D7)} -> 20.3616 | F7: 1#
A8: 二层T型钢龙骨玻璃幕墙（8+1.52PVB+8㎜全超白钢化夹层玻璃） | B8: 1#南立面2/01~22轴 | C8: ㎡ | D8: （7.2+1.65+0.985）*3.035+（2.785+30.8+3.9+3.58+5.785）*3.035 | E8: {=+EVALUATE(D8)} -> 172.03897 | F8: 1#
A9: 二层T型钢龙骨玻璃幕墙（8+1.52PVB+8㎜全超白钢化夹层玻璃）（直+弯弧）（直段宽度300㎜+弧长942㎜，圆弧半径600㎜，高3035㎜） | B9: 1#南立面2/01~22轴 | C9: ㎡ | D9: （0.942+0.3）*2*3.035 | E9: {=+EVALUATE(D9)} -> 7.53894 | F9: 1#
A10: 二层T型钢龙骨玻璃幕墙（8+1.52PVB+8㎜全超白钢化夹层玻璃）（弯弧）（弧长1414㎜，圆弧半径900㎜，高3035㎜） | B10: 1#南立面2/01~22轴 | C10: ㎡ | D10: （1.414*4）*2*3.035 | E10: {=+EVALUATE(D10)} -> 34.33192 | F10: 1#
A11: 首层明框玻璃幕墙（10Low-E(双银)+12A+10㎜全超白钢化中空玻璃） | B11: 1#北立面24~4轴，24~15轴二层 | C11: ㎡ | D11: （18.5+1.9-1.8*4-2.48）*2.5 | E11: {=+EVALUATE(D11)} -> 26.8 | F11: 1#
A12: 首层明框玻璃幕墙（10Low-E(双银)+12A+10㎜全超白钢化中空玻璃）（直+弯弧+直）（直段宽度210㎜+弧长1414㎜+直段宽度210㎜，圆弧半径900㎜，高2500㎜） | B12: 1#北立面24~4轴 | C12: ㎡ | D12: （0.21+1.414+0.21）*2.5*5 | E12: {=+EVALUATE(D12)} -> 22.925 | F12: 1#
A13: 首层明框玻璃幕墙（15Low-E(双银)+12A+15㎜全超白钢化中空玻璃） | B13: 北立面24~3/01轴 | C13: ㎡ | D13: （3.103*2）*2.5 | E13: {=+EVALUATE(D13)} -> 15.515 | F13: 1#
A14: 首层明框玻璃幕墙（8+1.52PVB+8Low-E(双银)+12A+8+1.52PVB+8㎜全超白钢化夹层中空玻璃）（超高）（宽2175㎜，高6800㎜） | B14: 北立面4~2轴 | C14: ㎡ | D14: 2.175*6.8 | E14: {=+EVALUATE(D14)} -> 14.79 | F14: 1#
... A55: 二层明框玻璃幕墙（10Low-E(双银)+12A+10㎜全超白钢化中空玻璃） | B55: 2#北立面18~2/01轴,3剖 | C55: ㎡ | D55: （1.85+15.08+1.09*2+4.49+6.3+2.7）*2.345 | E55: {=+EVALUATE(D55)} -> 76.447 | F55: 2#
A56: 二层明框玻璃幕墙（10Low-E(双银)+12A+10㎜全超白钢化中空玻璃）（直+弯弧+直）（直段宽度210㎜+弧长1414㎜+直段宽度210㎜，圆弧半径900㎜，高2345㎜） | B56: 2#北立面18~2/01轴,3剖 | C56: ㎡ | D56: （0.21*2+1.414）*2.345*4+（0.21*2+1.095）*2.345 | E56: {=+EVALUATE(D56)} -> 20.755595 | F56: 2# | H56: =E56+E50 -> 23.029755
A57: 玻璃栏板
A58: 6+1.14PVB+6㎜超白钢化夹层玻璃栏杆 | B58: 1#楼 | C58: m | D58: 26.549-（0.27+0.754）*2 | E58: {=+EVALUATE(D58)} -> 24.501 | F58: 1#
A59: 6+1.14PVB+6㎜超白钢化夹层玻璃栏杆（弧形） | B59: 1#楼 | C59: m | D59: （0.27+0.754）*2 | E59: {=+EVALUATE(D59)} -> 2.048 | F59: 1#
A60: 6+1.14PVB+6㎜超白钢化夹层玻璃栏杆 | B60: 2#楼 | C60: m | D60: 66.281-（0.46+0.754+0.44+0.754）-（0.44+0.754+0.41+0.754）-（0.19+0.754+0.19+0.754） | E60: {=+EVALUATE(D60)} -> 59.627 | F60: 2#
A61: 6+1.14PVB+6㎜超白钢化夹层玻璃栏杆（弧形） | B61: 2#楼 | C61: m | D61: （0.46+0.754+0.44+0.754）+（0.44+0.754+0.41+0.754）+（0.19+0.754+0.19+0.754） | E61: {=+EVALUATE(D61)} -> 6.654 | F61: 2#
A63: 地弹门 | E63: =SUM(E64:E70) -> 138.492
A64: 地弹门（6Low-E(双银)+12A+6㎜全超白钢化中空玻璃） | B64: 1#楼南立面 | C64: ㎡ | D64: 1.8*3.6 | E64: {=+EVALUATE(D64)} -> 6.48 | F64: 1#
A65: 地弹门（6Low-E(双银)+12A+6㎜全超白钢化中空玻璃） | B65: 1#楼北立面 | C65: ㎡ | D65: 1.8*2.5*9 | E65: {=+EVALUATE(D65)} -> 40.5 | F65: 1#
A66: 地弹门（6Low-E(双银)+12A+6㎜全超白钢化中空玻璃） | B66: 2#楼南立面 | C66: ㎡ | D66: 0.9*3.6*2 | E66: {=+EVALUATE(D66)} -> 6.48 | F66: 2#
A67: 地弹门（6Low-E(双银)+12A+6㎜全超白钢化中空玻璃） | B67: 2#楼南立面 | C67: ㎡ | D67: 1.75*3.6+1.75*3.6+1.8*3.6 | E67: {=+EVALUATE(D67)} -> 19.08 | F67: 2#
A68: 地弹门（6Low-E(双银)+12A+6㎜全超白钢化中空玻璃） | B68: 2#楼北立面 | C68: ㎡ | D68: 1.8*2.5*8 | E68: {=+EVALUATE(D68)} -> 36 | F68: 2#
A69: 地弹门（6Low-E(双银)+12A+6㎜全超白钢化中空玻璃） | B69: 2#楼北立面二层 | C69: ㎡ | D69: 1.8*2.33+1.8*2.345*4 | E69: {=+EVALUATE(D69)} -> 21.078 | F69: 2#
